Workbook

Sheet 데이터
A1: {"조건절":"Y","DB테이블명":"EGENE.ESO_CM","컬럼명":"CM_ID"} | B1: {"조건절":"N","DB테이블명":"EGENE.ESO_CM","컬럼명":"CM_NAME"} | C1: {"조건절":"N","DB테이블명":"EGENE.ESO_CM","컬럼명":"CM_TCM_ID"} | D1: {"조건절":"N","DB테이블명":"EGENE.ESO_CM","컬럼명":"CM_IP"} | E1: {"조건절":"N","DB테이블명":"","컬럼명":""} | F1: {"조건절":"N","DB테이블명":"","컬럼명":""} | G1: {"조건절":"N","DB테이블명":"EGENE.ESO_CM","컬럼명":"CM_SVR_CAT_CD"} | H1: {"조건절":"N","DB테이블명":"","컬럼명":""} | I1: {"조건절":"N","DB테이블명":"EGENE.ESO_CM","컬럼명":"CM_CAT_CD"} | J1: {"조건절":"N","DB테이블명":"EGENE.ESO_CM","컬럼명":"CM_DESC"} | K1: {"조건절":"N","DB테이블명":"EGENE.ESO_CM","컬럼명":"CM_PID"} | L1: {"조건절":"N","DB테이블명":"EGENE.ESO_CM","컬럼명":"CM_ICM_WOG_ID"} | M1: {"조건절":"N","DB테이블명":"EGENE.ESO_CM","컬럼명":"CM_ICM_SEV_GRADE"} | N1: {"조건절":"N","DB테이블명":"EGENE.ESO_CM","컬럼명":"CM_LOCATION"} | O1: {"조건절":"N","DB테이블명":"EGENE.ESO_CM","컬럼명":"CM_FLOOR"} | P1: {"조건절":"N","DB테이블명":"EGENE.ESO_CM","컬럼명":"CM_MGR_DPT_ID"} | Q1: {"조건절":"N","DB테이블명":"EGENE.ESO_CM","컬럼명":"CM_MGR_EMP_ID"} | R1: {"조건절":"N","DB테이블명":"EGENE.ESO_CM","컬럼명":"CM_MGS_EMP_ID"} | S1: {"조건절":"N","DB테이블명":"EGENE.ESO_CM","컬럼명":"CM_OP_DPT_ID"} | T1: {"조건절":"N","DB테이블명":"EGENE.ESO_CM","컬럼명":"CM_OP_EMP_ID"} | U1: {"조건절":"N","DB테이블명":"EGENE.ESO_CM","컬럼명":"CM_OPS_EMP_ID"} | V1: {"조건절":"N","DB테이블명":"EGENE.ESO_CM","컬럼명":"CM_PCM_YN"} | W1: {"조건절":"N","DB테이블명":"EGENE.ESO_CM","컬럼명":"CM_PCM_PERIOD_YN"} | X1: {"조건절":"N","DB테이블명":"EGENE.ESO_CM","컬럼명":"CM_PCM_PLANSTOP_YN"} | Y1: {"조건절":"N","DB테이블명":"EGENE.ESO_CM","컬럼명":"CM_PCM_UNPERIOD_YN"} | Z1: {"조건절":"N","DB테이블명":"EGENE.ESO_CM","컬럼명":"CM_PCM_WOG_ID"} | AA1: {"조건절":"N","DB테이블명":"EGENE.ESO_CM","컬럼명":"CM_SVR_SER_NUM"} | AB1: {"조건절":"N","DB테이블명":"EGENE.ESO_CM","컬럼명":"CM_CTR_NUM"} | AC1: {"조건절":"N","DB테이블명":"EGENE.ESO_CM","컬럼명":"CM_SVR_CLA_NUM"} | AD1: {"조건절":"N","DB테이블명":"EGENE.ESO_CM","컬럼명":"CM_AST_NUM"} | AE1: {"조건절":"N","DB테이블명":"EGENE.ESO_CM","컬럼명":"CM_MODEL_NAME"} | AF1: {"조건절":"N","DB테이블명":"EGENE.ESO_CM","컬럼명":"CM_RACK_NUM"} | AG1: {"조건절":"N","DB테이블명":"EGENE.ESO_CM","컬럼명":"CM_OS"} | AH1: {"조건절":"N","DB테이블명":"EGENE.ESO_CM","컬럼명":"CM_OS_VERSION"} | AI1: {"조건절":"N","DB테이블명":"EGENE.ESO_CM","컬럼명":"CM_SYSMON_SOLUTION"} | AJ1: {"조건절":"N","DB테이블명":"EGENE.ESO_CM","컬럼명":"CM_OS_PATCH"} | AK1: {"조건절":"N","DB테이블명":"EGENE.ESO_CM","컬럼명":"CM_MAKE제조사"} | AL1: {"조건절":"N","DB테이블명":"EGENE.ESO_CM","컬럼명":"CM_CPU_NUM"} | AM1: {"조건절":"N","DB테이블명":"EGENE.ESO_CM","컬럼명":"CM_CPU_CORE_NUM"} | AN1: {"조건절":"N","DB테이블명":"EGENE.ESO_CM","컬럼명":"CM_CPU_SPEED"} | AO1: {"조건절":"N","DB테이블명":"EGENE.ESO_CM","컬럼명":"CM_CPU_TYPE"} | AP1: {"조건절":"N","DB테이블명":"EGENE.ESO_CM","컬럼명":"CM_TPMC"} | AQ1: {"조건절":"N","DB테이블명":"EGENE.ESO_CM","컬럼명":"CM_MEMORY"} | AR1: {"조건절":"N","DB테이블명":"EGENE.ESO_CM","컬럼명":"CM_IN_DISK"} | AS1: {"조건절":"N","DB테이블명":"EGENE.ESO_CM","컬럼명":"CM_NET_CAT_CD"} | AT1: {"조건절":"N","DB테이블명":"EGENE.ESO_CM","컬럼명":"CM_NET_SPEED"} | AU1: {"조건절":"N","DB테이블명":"EGENE.ESO_CM","컬럼명":"CM_NET_IP"} | AV1: {"조건절":"N","DB테이블명":"EGENE.ESO_CM","컬럼명":"CM_SVC_CAT_CD"} | AW1: {"조건절":"N","DB테이블명":"EGENE.ESO_CM","컬럼명":"CM_SVR_CLA_CD"} | AX1: {"조건절":"N","DB테이블명":"EGENE.ESO_CM","컬럼명":"CM_APP"} | AY1: {"조건절":"N","DB테이블명":"EGENE.ESO_CM","컬럼명":"CM_BIZ_NAME"} | AZ1: {"조건절":"N","DB테이블명":"EGENE.ESO_CM","컬럼명":"CM_BIZ_NAME_DESC"} | BA1: {"조건절":"N","DB테이블명":"EGENE.ESO_CM","컬럼명":"CM_VIR_SOLUTION"} | BB1: {"조건절":"N","DB테이블명":"EGENE.ESO_CM","컬럼명":"CM_DR_SOLUTION"} | BC1: {"조건절":"N","DB테이블명":"EGENE.ESO_CM","컬럼명":"CM_BAK_SOLUTION"} | BD1: {"조건절":"N","DB테이블명":"EGENE.ESO_CM","컬럼명":"CM_SVC_TIME"} | BE1: {"조건절":"N","DB테이블명":"EGENE.ESO_CM","컬럼명":"CM_SUPPLY"} | BF1: {"조건절":"N","DB테이블명":"EGENE.ESO_CM","컬럼명":"CM_SVR_CARD"} | BG1: {"조건절":"N","DB테이블명":"EGENE.ESO_CM","컬럼명":"CM_INFO_ETC"} | BH1: {"조건절":"N","DB테이블명":"EGENE.ESO_CM","컬럼명":"CM_SVR_ETC"} | BI1: {"조건절":"N","DB테이블명":"EGENE.ESO_CM","컬럼명":"CM_MOD_EMP_ID"} | BJ1: {"조건절":"N","DB테이블명":"EGENE.ESO_CM","컬럼명":"CM_MOD_DTTM"}
A2: 구성ID | B2: 구성항목명 | C2: 현행화ID | D2: IP | E2: AD비교 | F2: AD_VERSION | G2: 장비구분 | H2: 항목명중복건수 | I2: 서버구분 | J2: 구성항목명 | K2: 구성항목설명 | L2: 인시던트처리직무 | M2: 인시던트심각도 | N2: 설치지역 | O2: 설치층수 | P2: 관리부서 | Q2: 관리직원(정) | R2: 관리직원(부) | S2: 운영부서 | T2: 운영직원(정) | U2: 운영직원(부) | V2: 예방점검대상유무 | W2: 예방점검대상유무 | X2: 정기점검대상여부 | Y2: 계획정지대상여부 | Z2: 특별점검대상여부 | AA2: 서버관리번호 | AB2: 계약번호 | AC2: 물품분류번호 | AD2: 물품번호 | AE2: 모델명 | AF2: Rack번호 | AG2: 운영체제 | AH2: 운영체제버전 | AI2: 운영체제관리툴명 | AJ2: 운영체제패치버전 | AK2: 제조사 | AL2: CPU수 | AM2: CORE수(물리/논리) | AN2: CPU속도(GHz) | AO2: CPU타입 | AP2: CPU_TPMC | AQ2: 메모리용량(GB) | AR2: 내장디스크용량(GB) | AS2: 네트워크방식 | AT2: 네트워크속도 | AU2: 네트워크IP주소 | AV2: 가동구분 | AW2: 서버분류 | AX2: 어플리케이션코드 | AY2: 업무명 | AZ2: 상세업무명 | BA2: 가상화솔루션명 | BB2: 재해복구솔루션명 | BC2: 백업솔루션명 | BD2: 서비스제공시간 | BE2: 공급사 | BF2: 서버Card정보 | BG2: 구성정보비고 | BH2: 관리정보비고 | BI2: 수정자 | BJ2: 수정일시
A3: CM2009-000051 | B3: begapd01 | C3: BEGAPD01_10.38.137.61 | D3: 10.38.137.61 | H3: 0 | I3: 서버논리|KBCMCAT03002 | J3: begapd01 | K3: 서울ROC 통합정보 AP 개발 | L3: 서버OS(LINUX계열)|SWA00073_SSM | M3: 5|KBCMSEVGD05 | N3: 여의도센터|KBCMLOCATION002 | P3: 시스템운영부|103640 | Q3: 인프라시스템부(P) 양동민|5492242 | R3: 인프라시스템부(P) 안정은|2855831 | V3: 아니요|0 | W3: 아니요|0 | X3: 아니요|0 | Y3: 아니요|0 | Z3: 아니요|0 | AG3: Linux | AH3: Red Hat Enterprise Linux Server release 7.6 (Maipo) | AK3: VMware, Inc. | AL3: 2 | AM3: 2/2 | AN3: 2.4 | AQ3: 31 | AR3: 306 | BH3: LINUX | BJ3: 20220409152539
A4: CM2009-000052 | B4: begapo01 | C4: BEGAPO01_10.37.37.61 | D4: 10.37.37.61 | H4: 0 | I4: 서버논리|KBCMCAT03002 | J4: begapo01 | K4: 서울ROC 통합정보 AP | L4: 서버OS(LINUX계열)|SWA00073_SSM | M4: 3|KBCMSEVGD03 | N4: 김포센터|KBCMLOCATION001 | P4: 시스템운영부|103640 | Q4: 인프라시스템부(P) 양동민|5492242 | R4: 인프라시스템부(P) 안정은|2855831 | V4: 예|1 | W4: 예|1 | X4: 예|1 | Y4: 예|1 | Z4: 예|1 | AG4: Linux | AH4: Red Hat Enterprise Linux Server release 7.6 (Maipo) | AK4: VMware, Inc. | AL4: 4 | AM4: 4/4 | AN4: 2.4 | AQ4: 63 | AR4: 406 | BH4: LINUX | BJ4: 20210604110747
A5: CM2004-000581 | B5: begapo11 | C5: BEGAPO11_10.37.38.101 | D5: 10.37.38.101 | H5: 0 | I5: 서버논리|KBCMCAT03002 | J5: begapo11 | L5: 서버OS(LINUX계열)|SWA00073_SSM | M5: 3|KBCMSEVGD03 | N5: 김포센터|KBCMLOCATION001 | P5: 시스템운영부|103640 | Q5: 인프라시스템부(P) 양동민|5492242 | R5: 인프라시스템부(P) 안정은|2855831 | V5: 예|1 | W5: 예|1 | X5: 예|1 | Y5: 예|1 | Z5: 예|1 | AG5: Linux | AH5: Red Hat Enterprise Linux Server release 7.6 (Maipo) | AK5: HPE | AL5: 2 | AM5: 4/8 | AN5: 3.6 | AQ5: 31 | AR5: 22423 | BH5: LINUX | BJ5: 20210916083435
A6: CM2009-000053 | B6: begaps01 | C6: BEGAPS01_10.38.37.61 | D6: 10.38.37.61 | H6: 0 | I6: 서버논리|KBCMCAT03002 | J6: begaps01 | K6: 서울ROC 통합정보 AP 스테이징 | L6: 서버OS(LINUX계열)|SWA00073_SSM | M6: 5|KBCMSEVGD05 | N6: 여의도센터|KBCMLOCATION002 | P6: 시스템운영부|103640 | Q6: 인프라시스템부(P) 양동민|5492242 | R6: 인프라시스템부(P) 안정은|2855831 | V6: 아니요|0 | W6: 아니요|0 | X6: 아니요|0 | Y6: 아니요|0 | Z6: 아니요|0 | AG6: Linux | AH6: Red Hat Enterprise Linux Server release 7.6 (Maipo) | AK6: VMware, Inc. | AL6: 2 | AM6: 2/2 | AN6: 2.4 | AQ6: 31 | AR6: 306 | BH6: LINUX | BJ6: 20210604103702
A7: CM2009-000054 | B7: begdbd01 | C7: BEGDBD01_10.38.138.61 | D7: 10.38.138.61 | H7: 0 | I7: 서버논리|KBCMCAT03002 | J7: begdbd01 | K7: 서울ROC 통합정보DB | L7: 서버OS(LINUX계열)|SWA00073_SSM | M7: 5|KBCMSEVGD05 | N7: 여의도센터|KBCMLOCATION002 | P7: 시스템운영부|103640 | Q7: 인프라시스템부(P) 양동민|5492242 | R7: 인프라시스템부(P) 안정은|2855831 | V7: 아니요|0 | W7: 아니요|0 | X7: 아니요|0 | Y7: 아니요|0 | Z7: 아니요|0 | AG7: Linux | AH7: Red Hat Enterprise Linux Server release 7.6 (Maipo) | AK7: HPE | AL7: 2 | AM7: 2/2 | AN7: 3.6 | AQ7: 31 | AR7: 2690 | BH7: LINUX | BJ7: 20220409152539
A8: CM2009-000055 | B8: begdbo01 | C8: BEGDBO01_10.37.38.61 | D8: 10.37.38.61 | H8: 0 | I8: 서버논리|KBCMCAT03002 | J8: begdbo01 | K8: 서울ROC 통합정보DB | L8: 서버OS(LINUX계열)|SWA00073_SSM | M8: 3|KBCMSEVGD03 | N8: 김포센터|KBCMLOCATION001 | P8: 시스템운영부|103640 | Q8: 인프라시스템부(P) 양동민|5492242 | R8: 인프라시스템부(P) 안정은|2855831 | V8: 예|1 | W8: 예|1 | X8: 예|1 | Y8: 예|1 | Z8: 예|1 | AG8: Linux | AH8: Red Hat Enterprise Linux Server release 7.6 (Maipo) | AK8: HPE | AL8: 2 | AM8: 4/8 | AN8: 3.6 | AQ8: 62 | AR8: 19049 | BH8: LINUX | BJ8: 20210604110747
A9: CM2009-000056 | B9: begdbs01 | C9: BEGDBS01_10.38.38.61 | D9: 10.38.38.61 | H9: 0 | I9: 서버논리|KBCMCAT03002 | J9: begdbs01 | K9: 서울ROC 통합정보DB | L9: 서버OS(LINUX계열)|SWA00073_SSM | M9: 5|KBCMSEVGD05 | N9: 여의도센터|KBCMLOCATION002 | P9: 시스템운영부|103640 | Q9: 인프라시스템부(P) 양동민|5492242 | R9: 인프라시스템부(P) 안정은|2855831 | V9: 아니요|0 | W9: 아니요|0 | X9: 아니요|0 | Y9: 아니요|0 | Z9: 아니요|0 | AG9: Linux | AH9: Red Hat Enterprise Linux Server release 7.6 (Maipo) | AK9: HPE | AL9: 2 | AM9: 2/4 | AN9: 3.6 | AQ9: 31 | AR9: 17177 | BH9: LINUX | BJ9: 20210604103702
A10: CM2009-000057 | B10: belapd01 | C10: BELAPD01_10.38.137.51 | D10: 10.38.137.51 | H10: 0 | I10: 서버논리|KBCMCAT03002 | J10: belapd01 | K10: 서울ROC 정보AP | L10: 서버OS(LINUX계열)|SWA00073_SSM | M10: 5|KBCMSEVGD05 | N10: 여의도센터|KBCMLOCATION002 | P10: 시스템운영부|103640 | Q10: 인프라시스템부(P) 양동민|5492242 | R10: 인프라시스템부(P) 안정은|2855831 | V10: 아니요|0 | W10: 아니요|0 | X10: 아니요|0 | Y10: 아니요|0 | Z10: 아니요|0 | AG10: Linux | AH10: Red Hat Enterprise Linux Server release 7.6 (Maipo) | AK10: VMware, Inc. | AL10: 2 | AM10: 2/2 | AN10: 2.4 | AQ10: 31 | AR10: 306 | BH10: LINUX | BJ10: 20220409152539
A11: CM_SVR02744 | B11: belapd11 | C11: BELAPD11_10.38.131.12 | D11: 10.38.131.12 | H11: 0 | I11: 서버논리|KBCMCAT03002 | J11: belapd11 | L11: 서버OS(LINUX계열)|SWA00073_SSM | M11: 5|KBCMSEVGD05 | N11: 여의도센터|KBCMLOCATION002 | O11: 4|4 | P11: 시스템운영부|103640 | Q11: 인프라시스템부(P) 양동민|5492242 | R11: 인프라시스템부(P) 안정은|2855831 | S11: IT서비스개발부|125340 | T11: 글로벌플랫폼부(P) 이동윤|2829879 | V11: 아니요|0 | W11: 아니요|0 | X11: 아니요|0 | Y11: 아니요|0 | Z11: 아니요|0 | AA11: 3S4ZLX2 | AF11: 4F-A12-06 | AG11: Linux | AH11: Red Hat Enterprise Linux Server release 7.6 (Maipo) | AK11: VMware, Inc. | AL11: 5 | AM11: 5/5 | AN11: 2.6 | AP11: 0 | AQ11: 157 | AR11: 2354 | AW11: 정보성 업무 영업점 접점 서버|KBCMSVRCLA005 | AY11: 뉴욕AML AP 개발서버 | AZ11: 뉴욕AML AP 개발서버 | BA11: VMWare | BH11: LINUX | BJ11: 20210604103703
A12: CM2009-000058 | B12: belapo01 | C12: BELAPO01_10.37.37.51 | D12: 10.37.37.51 | H12: 0 | I12: 서버논리|KBCMCAT03002 | J12: belapo01 | K12: 서울ROC 정보AP | L12: 서버OS(LINUX계열)|SWA00073_SSM | M12: 3|KBCMSEVGD03 | N12: 김포센터|KBCMLOCATION001 | P12: 시스템운영부|103640 | Q12: 인프라시스템부(P) 양동민|5492242 | R12: 인프라시스템부(P) 안정은|2855831 | V12: 예|1 | W12: 예|1 | X12: 예|1 | Y12: 예|1 | Z12: 예|1 | AG12: Linux | AH12: Red Hat Enterprise Linux Server release 7.6 (Maipo) | AK12: VMware, Inc. | AL12: 2 | AM12: 2/2 | AN12: 2.4 | AQ12: 31 | AR12: 406 | BH12: LINUX | BJ12: 20210604110747

Sheet 코드
A1: 인시던트심각도 | B1: 설치지역 | C1: 층수 | D1: 부서명 | E1: 직원명 | F1: 예_아니요 | G1: CPU타입 | H1: 네트워크방식 | I1: 네트워크속도 | J1: 가동구분 | K1: 서버분류
A2: 1|KBCMSEVGD01 | B2: 김포센터|KBCMLOCATION001 | C2: 1|1 | D2: 마이데이터부(P)|100150 | E2: 구로동종합금융센터 유수연|2841530 | F2: 예|1 | G2: Intel|KBCMCPUTYPE001 | H2: 은행자산|KBCMNETCAT001 | I2: Fast Ethernet|KBCMNETSPEED001 | J2: 24/365|KBCMSVCCAT001 | K2: 계정성 업무 G/W 서버|KBCMSVRCLA001
A3: 2|KBCMSEVGD02 | B3: 여의도센터|KBCMLOCATION002 | C3: 2|2 | D3: 기업금융솔루션부(P)(솔루션1부(상품))|106651 | E3: 스마트상담부 유수영|2841543 | F3: 아니요|0 | G3: Itainum|KBCMCPUTYPE002 | H3: 계열사자산|KBCMNETCAT002 | I3: GIGA Ethernet|KBCMNETSPEED002 | J3: Hotstandby|KBCMSVCCAT002 | K3: 계정성 업무 고객 접점 서버|KBCMSVRCLA002
A4: 3|KBCMSEVGD03 | B4: 염창센터|KBCMLOCATION003 | C4: 3|3 | D4: 영업플랫폼부(P)|109730 | E4: 잠실중앙지점 유은희|2841574 | G4: PA-RISC|KBCMCPUTYPE003 | H4: 부외자산|KBCMNETCAT003 | I4: 10Gb FC|KBCMNETSPEED004 | J4: SLB|KBCMSVCCAT003 | K4: 계정성 업무 영업점 접점 서버|KBCMSVRCLA003
A5: 4|KBCMSEVGD04 | B5: 대전센터|KBCMLOCATION004 | C5: 4|4 | D5: 개인마케팅부(마케팅1부)|110260 | E5: 신월뉴타운지점 유석호|2841470 | G5: XEON|KBCMCPUTYPE004 | I5: 기타|KBCMNETSPEED003 | J5: 영업시간내|KBCMSVCCAT004 | K5: 정보성 업무 고객 접점 서버|KBCMSVRCLA004
A6: 5|KBCMSEVGD05 | B6: 기타|KBCMLOCATION005 | C6: 5|5 | D6: 리브플랫폼부(P)|110340 | E6: 중부지역그룹 윤은정|2842319 | G6: x86|KBCMCPUTYPE005 | J6: 평일운영|KBCMSVCCAT005 | K6: 정보성 업무 영업점 접점 서버|KBCMSVRCLA005
D7: 인증사업부(P)|110350 | E7: 스마트상담부(대전상담팀) 유세민|2841509 | G7: Power PC|KBCMCPUTYPE006 | J7: 기타|KBCMSVCCAT006 | K7: 본부부서 사용서버중 주요서버|KBCMSVRCLA006
D8: KB부동산플랫폼부(P)|110360 | E8: 목포종합금융센터 유수연|2841526 | G8: RS64-IV|KBCMCPUTYPE007 | K8: 관리성 업무 주요서버|KBCMSVRCLA007
D9: 리브모바일부(P)|110370 | E9: 중곡동지점 유인선|2841696 | G9: POWER4|KBCMCPUTYPE008 | K9: 보안 업무 주요서버|KBCMSVRCLA008
D10: 기업금융솔루션부(P)(솔루션3부(기업뱅킹))|110390 | E10: 양천지점 유주연|2841756 | G10: POWER5|KBCMCPUTYPE009 | K10: 기타 주요서버|KBCMSVRCLA009
D11: 기관영업부(P)|110430 | E11: 마산종합금융센터 유주연|2841760 | G11: POWER6|KBCMCPUTYPE010 | K11: 계정성 업무 중 기타 서버|KBCMSVRCLA010
D12: 미래컨택센터추진부|110440 | E12: 합정역지점 유주희|2841773 | G12: POWER7|KBCMCPUTYPE011 | K12: 본부부서 사용서버|KBCMSVRCLA011
D13: 스마트상담플랫폼부(P)|110450 | E13: 일산북종합금융센터 유영미|2841591 | G13: SPARC64-VI|KBCMCPUTYPE012 | K13: 관리성 업무 서버|KBCMSVRCLA012
D14: 글로벌플랫폼부(P)|110460 | E14: 장위동지점 유영숙|2841603 | G14: SPARC64-VII|KBCMCPUTYPE013 | K14: 보안 업부 서버|KBCMSVRCLA013
D15: 자본시장플랫폼부(P)|110480 | E15: 이문동지점 유영애|2841621 | G15: SPARC64-VII+|KBCMCPUTYPE014 | K15: 테스트 업무 서버|KBCMSVRCLA014
D16: 펀드서비스부(P)|123240 | E16: 용현남종합금융센터 유용희|2841651 | G16: SPARC-T3|KBCMCPUTYPE015 | K16: 개발 업무 서버|KBCMSVRCLA015
D17: 테크그룹(IT자체감사팀)|130710 | E17: 유성종합금융센터 유은영|2841679 | G17: SPARC-T4|KBCMCPUTYPE016 | K17: 미사용서버|KBCMSVRCLA016
D18: 데이터기획부|130801 | E18: 구월동종합금융센터 유은혜|2841682 | G18: ULTRASPARC|KBCMCPUTYPE017 | K18: 불용대상 서버|KBCMSVRCLA017
D19: 기업금융솔루션부(P)(솔루션2부(서비스))|182440 | E19: 노원종합금융센터 육은선|2841969 | G19: ULTRASPARC-II|KBCMCPUTYPE018
D20: KB InsighT|185421 | E20: 재무기획부 유지선|2841791 | G20: ULTRASPARC-III+|KBCMCPUTYPE019
D21: 개인마케팅부(마케팅2부)|460001 | E21: 송우종합금융센터 유지영|2841802 | G21: ULTRASPARC-IIIi|KBCMCPUTYPE020
D22: 스타뱅킹부(P)(스뱅1부(상품·서비스))|460002 | E22: 시화지점 유지영|2841816 | G22: ULTRASPARC-IV|KBCMCPUTYPE021
D23: 스타뱅킹부(P)(스뱅2부(고객경험))|460003 | E23: 안동지점 유지은|2841833 | G23: ULTRASPARC-IV+|KBCMCPUTYPE022
D24: 스타뱅킹부(P)(스뱅3부(인프라))|460004 | E24: 노원종합금융센터 유찬희|2841851 | G24: ULTRASPARC-T1|KBCMCPUTYPE023
D25: 디지털신사업부(P)|460005 | E25: 중계동지점 유하느|2841878 | G25: ULTRASPARC-T2|KBCMCPUTYPE024
D26: 고객경험디자인센터|460007 | E26: 도안가수원지점 유현주|2841895 | G26: POWER9|KBCMCPUTYPE025
D27: 디지털콘텐츠센터|460008 | E27: 정왕동지점 유현진|2841907 | G27: SPARC64-XII|KBCMCPUTYPE026
D28: DT전략부|655550 | E28: 부산·울산·경남지역그룹 유혜진|2841941 | G28: 기타|KBCMCPUTYPE027
D29: 테크그룹|880000 | E29: 둔산갤러리아지점 윤연승|2841986
D30: 테크기획부|880010 | E30: 대연동종합금융센터 윤교린|2841990
D31: 테크혁신본부(애자일빌드팀)|880501 | E31: 스마트고객부 윤나라|2842015
D32: 테크혁신본부(코어뱅킹혁신팀)|880502 | E32: 대전은행동종합금융센터 윤도희|2842029
D33: 수신코어뱅킹부(P)|881100 | E33: 동두천지점 윤미선|2842032
D34: 여신코어뱅킹부(P)|881200 | E34: 장기동지점 윤미선|2842046
D35: 연계시스템개발부(P)|881300 | E35: 증평지점 윤미소|2842050
D36: 혁신기술개발부(P)|881400 | E36: 안양동지점 윤미영|2842063
D37: 데이터분석부(P)|882200 | E37: 서울역지점 윤상희|2842081
D38: 데이터엔지니어링부(P)|882300 | E38: 평택중앙종합금융센터 윤성숙|2842110
D39: 금융AI센터|882400 | E39: 스마트고객부(대전고객팀) 윤수진|2842168
D40: 테크인프라본부(IT장애관리팀)|883001 | E40: 신사중앙지점 윤수진|2842171
...

Sheet 검증
A1: 데이터검증 | B1: 인시던트심각도 | C1: 설치지역 | D1: 설치층수 | E1: 관리부서 | F1: 관리직원(정) | G1: 관리직원(부) | H1: 운영부서 | I1: 운영직원(정) | J1: 운영직원(부) | K1: 예방점검대상유무 | L1: 예방점검대상유무 | M1: 정기점검대상여부 | N1: 계획정지대상여부 | O1: CPU타입 | P1: 네트워크방식 | Q1: 네트워크속도 | R1: 가동구분 | S1: 서버분류
A2: =IF(COUNTIF(B2:S2,"*!"),COUNTIF(B2:S2,"*!")&"건 이상 검증 확인 필요","") -> 1건 이상 검증 확인 필요 | C2: =IF(LENB(TRIM(데이터!N3))=0,"",IF(ISERROR(VLOOKUP(데이터!N3,코드!$B$2:$B$7,1,0)),"데이터!N3 코드값을 잘못입력하였습니다!","")) | D2: =IF(LENB(TRIM(데이터!O3))=0,"",IF(ISERROR(VLOOKUP(데이터!O3,코드!$C$2:$C$7,1,0)),"데이터!O3 코드값을 잘못입력하였습니다!","")) | E2: =IF(LENB(TRIM(데이터!P3))=0,"",IF(ISERROR(VLOOKUP(데이터!P3,코드!$D$2:$D$47,1,0)),"데이터!P3 코드값을 잘못입력하였습니다!","")) -> 데이터!P3 코드값을 잘못입력하였습니다! | F2: =IF(LENB(TRIM(데이터!Q3))=0,"",IF(ISERROR(VLOOKUP(데이터!Q3,코드!$E$2:$E$13158,1,0)),"데이터!Q3 코드값을 잘못입력하였습니다!","")) | G2: =IF(LENB(TRIM(데이터!R3))=0,"",IF(ISERROR(VLOOKUP(데이터!R3,코드!$E$2:$E$13158,1,0)),"데이터!R3 코드값을 잘못입력하였습니다!","")) | H2: =IF(LENB(TRIM(데이터!S3))=0,"",IF(ISERROR(VLOOKUP(데이터!S3,코드!$D$2:$D$47,1,0)),"데이터!S3 코드값을 잘못입력하였습니다!","")) | I2: =IF(LENB(TRIM(데이터!T3))=0,"",IF(ISERROR(VLOOKUP(데이터!T3,코드!$E$2:$E$13158,1,0)),"데이터!T3 코드값을 잘못입력하였습니다!","")) | J2: =IF(LENB(TRIM(데이터!U3))=0,"",IF(ISERROR(VLOOKUP(데이터!U3,코드!$E$2:$E$13158,1,0)),"데이터!U3 코드값을 잘못입력하였습니다!","")) | K2: =IF(LENB(TRIM(데이터!V3))=0,"",IF(ISERROR(VLOOKUP(데이터!V3,코드!$F$2:$F$4,1,0)),"데이터!V3 코드값을 잘못입력하였습니다!","")) | L2: =IF(LENB(TRIM(데이터!W3))=0,"",IF(ISERROR(VLOOKUP(데이터!W3,코드!$F$2:$F$4,1,0)),"데이터!W3 코드값을 잘못입력하였습니다!","")) | M2: =IF(LENB(TRIM(데이터!X3))=0,"",IF(ISERROR(VLOOKUP(데이터!X3,코드!$F$2:$F$4,1,0)),"데이터!X3 코드값을 잘못입력하였습니다!","")) | N2: =IF(LENB(TRIM(데이터!Y3))=0,"",IF(ISERROR(VLOOKUP(데이터!Y3,코드!$F$2:$F$4,1,0)),"데이터!Y3 코드값을 잘못입력하였습니다!","")) | O2: =IF(LENB(TRIM(데이터!AO3))=0,"",IF(ISERROR(VLOOKUP(데이터!AO3,코드!$G$2:$G$29,1,0)),"데이터!AO3 코드값을 잘못입력하였습니다!","")) | P2: =IF(LENB(TRIM(데이터!AS3))=0,"",IF(ISERROR(VLOOKUP(데이터!AS3,코드!$H$2:$H$5,1,0)),"데이터!AS3 코드값을 잘못입력하였습니다!","")) | Q2: =IF(LENB(TRIM(데이터!AT3))=0,"",IF(ISERROR(VLOOKUP(데이터!AT3,코드!$I$2:$I$6,1,0)),"데이터!AT3 코드값을 잘못입력하였습니다!","")) | R2: =IF(LENB(TRIM(데이터!AV3))=0,"",IF(ISERROR(VLOOKUP(데이터!AV3,코드!$J$2:$J$8,1,0)),"데이터!AV3 코드값을 잘못입력하였습니다!","")) | S2: =IF(LENB(TRIM(데이터!AW3))=0,"",IF(ISERROR(VLOOKUP(데이터!AW3,코드!$K$2:$K$19,1,0)),"데이터!AW3 코드값을 잘못입력하였습니다!",""))
A3: =IF(COUNTIF(B3:S3,"*!"),COUNTIF(B3:S3,"*!")&"건 이상 검증 확인 필요","") -> 1건 이상 검증 확인 필요 | C3: =IF(LENB(TRIM(데이터!N4))=0,"",IF(ISERROR(VLOOKUP(데이터!N4,코드!$B$2:$B$7,1,0)),"데이터!N4 코드값을 잘못입력하였습니다!","")) | D3: =IF(LENB(TRIM(데이터!O4))=0,"",IF(ISERROR(VLOOKUP(데이터!O4,코드!$C$2:$C$7,1,0)),"데이터!O4 코드값을 잘못입력하였습니다!","")) | E3: =IF(LENB(TRIM(데이터!P4))=0,"",IF(ISERROR(VLOOKUP(데이터!P4,코드!$D$2:$D$47,1,0)),"데이터!P4 코드값을 잘못입력하였습니다!","")) -> 데이터!P4 코드값을 잘못입력하였습니다! | F3: =IF(LENB(TRIM(데이터!Q4))=0,"",IF(ISERROR(VLOOKUP(데이터!Q4,코드!$E$2:$E$13158,1,0)),"데이터!Q4 코드값을 잘못입력하였습니다!","")) | G3: =IF(LENB(TRIM(데이터!R4))=0,"",IF(ISERROR(VLOOKUP(데이터!R4,코드!$E$2:$E$13158,1,0)),"데이터!R4 코드값을 잘못입력하였습니다!","")) | H3: =IF(LENB(TRIM(데이터!S4))=0,"",IF(ISERROR(VLOOKUP(데이터!S4,코드!$D$2:$D$47,1,0)),"데이터!S4 코드값을 잘못입력하였습니다!","")) | I3: =IF(LENB(TRIM(데이터!T4))=0,"",IF(ISERROR(VLOOKUP(데이터!T4,코드!$E$2:$E$13158,1,0)),"데이터!T4 코드값을 잘못입력하였습니다!","")) | J3: =IF(LENB(TRIM(데이터!U4))=0,"",IF(ISERROR(VLOOKUP(데이터!U4,코드!$E$2:$E$13158,1,0)),"데이터!U4 코드값을 잘못입력하였습니다!","")) | K3: =IF(LENB(TRIM(데이터!V4))=0,"",IF(ISERROR(VLOOKUP(데이터!V4,코드!$F$2:$F$4,1,0)),"데이터!V4 코드값을 잘못입력하였습니다!","")) | L3: =IF(LENB(TRIM(데이터!W4))=0,"",IF(ISERROR(VLOOKUP(데이터!W4,코드!$F$2:$F$4,1,0)),"데이터!W4 코드값을 잘못입력하였습니다!","")) | M3: =IF(LENB(TRIM(데이터!X4))=0,"",IF(ISERROR(VLOOKUP(데이터!X4,코드!$F$2:$F$4,1,0)),"데이터!X4 코드값을 잘못입력하였습니다!","")) | N3: =IF(LENB(TRIM(데이터!Y4))=0,"",IF(ISERROR(VLOOKUP(데이터!Y4,코드!$F$2:$F$4,1,0)),"데이터!Y4 코드값을 잘못입력하였습니다!","")) | O3: =IF(LENB(TRIM(데이터!AO4))=0,"",IF(ISERROR(VLOOKUP(데이터!AO4,코드!$G$2:$G$29,1,0)),"데이터!AO4 코드값을 잘못입력하였습니다!","")) | P3: =IF(LENB(TRIM(데이터!AS4))=0,"",IF(ISERROR(VLOOKUP(데이터!AS4,코드!$H$2:$H$5,1,0)),"데이터!AS4 코드값을 잘못입력하였습니다!","")) | Q3: =IF(LENB(TRIM(데이터!AT4))=0,"",IF(ISERROR(VLOOKUP(데이터!AT4,코드!$I$2:$I$6,1,0)),"데이터!AT4 코드값을 잘못입력하였습니다!","")) | R3: =IF(LENB(TRIM(데이터!AV4))=0,"",IF(ISERROR(VLOOKUP(데이터!AV4,코드!$J$2:$J$8,1,0)),"데이터!AV4 코드값을 잘못입력하였습니다!","")) | S3: =IF(LENB(TRIM(데이터!AW4))=0,"",IF(ISERROR(VLOOKUP(데이터!AW4,코드!$K$2:$K$19,1,0)),"데이터!AW4 코드값을 잘못입력하였습니다!",""))
A4: =IF(COUNTIF(B4:S4,"*!"),COUNTIF(B4:S4,"*!")&"건 이상 검증 확인 필요","") -> 1건 이상 검증 확인 필요 | C4: =IF(LENB(TRIM(데이터!N5))=0,"",IF(ISERROR(VLOOKUP(데이터!N5,코드!$B$2:$B$7,1,0)),"데이터!N5 코드값을 잘못입력하였습니다!","")) | D4: =IF(LENB(TRIM(데이터!O5))=0,"",IF(ISERROR(VLOOKUP(데이터!O5,코드!$C$2:$C$7,1,0)),"데이터!O5 코드값을 잘못입력하였습니다!","")) | E4: =IF(LENB(TRIM(데이터!P5))=0,"",IF(ISERROR(VLOOKUP(데이터!P5,코드!$D$2:$D$47,1,0)),"데이터!P5 코드값을 잘못입력하였습니다!","")) -> 데이터!P5 코드값을 잘못입력하였습니다! | F4: =IF(LENB(TRIM(데이터!Q5))=0,"",IF(ISERROR(VLOOKUP(데이터!Q5,코드!$E$2:$E$13158,1,0)),"데이터!Q5 코드값을 잘못입력하였습니다!","")) | G4: =IF(LENB(TRIM(데이터!R5))=0,"",IF(ISERROR(VLOOKUP(데이터!R5,코드!$E$2:$E$13158,1,0)),"데이터!R5 코드값을 잘못입력하였습니다!","")) | H4: =IF(LENB(TRIM(데이터!S5))=0,"",IF(ISERROR(VLOOKUP(데이터!S5,코드!$D$2:$D$47,1,0)),"데이터!S5 코드값을 잘못입력하였습니다!","")) | I4: =IF(LENB(TRIM(데이터!T5))=0,"",IF(ISERROR(VLOOKUP(데이터!T5,코드!$E$2:$E$13158,1,0)),"데이터!T5 코드값을 잘못입력하였습니다!","")) | J4: =IF(LENB(TRIM(데이터!U5))=0,"",IF(ISERROR(VLOOKUP(데이터!U5,코드!$E$2:$E$13158,1,0)),"데이터!U5 코드값을 잘못입력하였습니다!","")) | K4: =IF(LENB(TRIM(데이터!V5))=0,"",IF(ISERROR(VLOOKUP(데이터!V5,코드!$F$2:$F$4,1,0)),"데이터!V5 코드값을 잘못입력하였습니다!","")) | L4: =IF(LENB(TRIM(데이터!W5))=0,"",IF(ISERROR(VLOOKUP(데이터!W5,코드!$F$2:$F$4,1,0)),"데이터!W5 코드값을 잘못입력하였습니다!","")) | M4: =IF(LENB(TRIM(데이터!X5))=0,"",IF(ISERROR(VLOOKUP(데이터!X5,코드!$F$2:$F$4,1,0)),"데이터!X5 코드값을 잘못입력하였습니다!","")) | N4: =IF(LENB(TRIM(데이터!Y5))=0,"",IF(ISERROR(VLOOKUP(데이터!Y5,코드!$F$2:$F$4,1,0)),"데이터!Y5 코드값을 잘못입력하였습니다!","")) | O4: =IF(LENB(TRIM(데이터!AO5))=0,"",IF(ISERROR(VLOOKUP(데이터!AO5,코드!$G$2:$G$29,1,0)),"데이터!AO5 코드값을 잘못입력하였습니다!","")) | P4: =IF(LENB(TRIM(데이터!AS5))=0,"",IF(ISERROR(VLOOKUP(데이터!AS5,코드!$H$2:$H$5,1,0)),"데이터!AS5 코드값을 잘못입력하였습니다!","")) | Q4: =IF(LENB(TRIM(데이터!AT5))=0,"",IF(ISERROR(VLOOKUP(데이터!AT5,코드!$I$2:$I$6,1,0)),"데이터!AT5 코드값을 잘못입력하였습니다!","")) | R4: =IF(LENB(TRIM(데이터!AV5))=0,"",IF(ISERROR(VLOOKUP(데이터!AV5,코드!$J$2:$J$8,1,0)),"데이터!AV5 코드값을 잘못입력하였습니다!","")) | S4: =IF(LENB(TRIM(데이터!AW5))=0,"",IF(ISERROR(VLOOKUP(데이터!AW5,코드!$K$2:$K$19,1,0)),"데이터!AW5 코드값을 잘못입력하였습니다!",""))
A5: =IF(COUNTIF(B5:S5,"*!"),COUNTIF(B5:S5,"*!")&"건 이상 검증 확인 필요","") -> 1건 이상 검증 확인 필요 | C5: =IF(LENB(TRIM(데이터!N6))=0,"",IF(ISERROR(VLOOKUP(데이터!N6,코드!$B$2:$B$7,1,0)),"데이터!N6 코드값을 잘못입력하였습니다!","")) | D5: =IF(LENB(TRIM(데이터!O6))=0,"",IF(ISERROR(VLOOKUP(데이터!O6,코드!$C$2:$C$7,1,0)),"데이터!O6 코드값을 잘못입력하였습니다!","")) | E5: =IF(LENB(TRIM(데이터!P6))=0,"",IF(ISERROR(VLOOKUP(데이터!P6,코드!$D$2:$D$47,1,0)),"데이터!P6 코드값을 잘못입력하였습니다!","")) -> 데이터!P6 코드값을 잘못입력하였습니다! | F5: =IF(LENB(TRIM(데이터!Q6))=0,"",IF(ISERROR(VLOOKUP(데이터!Q6,코드!$E$2:$E$13158,1,0)),"데이터!Q6 코드값을 잘못입력하였습니다!","")) | G5: =IF(LENB(TRIM(데이터!R6))=0,"",IF(ISERROR(VLOOKUP(데이터!R6,코드!$E$2:$E$13158,1,0)),"데이터!R6 코드값을 잘못입력하였습니다!","")) | H5: =IF(LENB(TRIM(데이터!S6))=0,"",IF(ISERROR(VLOOKUP(데이터!S6,코드!$D$2:$D$47,1,0)),"데이터!S6 코드값을 잘못입력하였습니다!","")) | I5: =IF(LENB(TRIM(데이터!T6))=0,"",IF(ISERROR(VLOOKUP(데이터!T6,코드!$E$2:$E$13158,1,0)),"데이터!T6 코드값을 잘못입력하였습니다!","")) | J5: =IF(LENB(TRIM(데이터!U6))=0,"",IF(ISERROR(VLOOKUP(데이터!U6,코드!$E$2:$E$13158,1,0)),"데이터!U6 코드값을 잘못입력하였습니다!","")) | K5: =IF(LENB(TRIM(데이터!V6))=0,"",IF(ISERROR(VLOOKUP(데이터!V6,코드!$F$2:$F$4,1,0)),"데이터!V6 코드값을 잘못입력하였습니다!","")) | L5: =IF(LENB(TRIM(데이터!W6))=0,"",IF(ISERROR(VLOOKUP(데이터!W6,코드!$F$2:$F$4,1,0)),"데이터!W6 코드값을 잘못입력하였습니다!","")) | M5: =IF(LENB(TRIM(데이터!X6))=0,"",IF(ISERROR(VLOOKUP(데이터!X6,코드!$F$2:$F$4,1,0)),"데이터!X6 코드값을 잘못입력하였습니다!","")) | N5: =IF(LENB(TRIM(데이터!Y6))=0,"",IF(ISERROR(VLOOKUP(데이터!Y6,코드!$F$2:$F$4,1,0)),"데이터!Y6 코드값을 잘못입력하였습니다!","")) | O5: =IF(LENB(TRIM(데이터!AO6))=0,"",IF(ISERROR(VLOOKUP(데이터!AO6,코드!$G$2:$G$29,1,0)),"데이터!AO6 코드값을 잘못입력하였습니다!","")) | P5: =IF(LENB(TRIM(데이터!AS6))=0,"",IF(ISERROR(VLOOKUP(데이터!AS6,코드!$H$2:$H$5,1,0)),"데이터!AS6 코드값을 잘못입력하였습니다!","")) | Q5: =IF(LENB(TRIM(데이터!AT6))=0,"",IF(ISERROR(VLOOKUP(데이터!AT6,코드!$I$2:$I$6,1,0)),"데이터!AT6 코드값을 잘못입력하였습니다!","")) | R5: =IF(LENB(TRIM(데이터!AV6))=0,"",IF(ISERROR(VLOOKUP(데이터!AV6,코드!$J$2:$J$8,1,0)),"데이터!AV6 코드값을 잘못입력하였습니다!","")) | S5: =IF(LENB(TRIM(데이터!AW6))=0,"",IF(ISERROR(VLOOKUP(데이터!AW6,코드!$K$2:$K$19,1,0)),"데이터!AW6 코드값을 잘못입력하였습니다!",""))
A6: =IF(COUNTIF(B6:S6,"*!"),COUNTIF(B6:S6,"*!")&"건 이상 검증 확인 필요","") -> 1건 이상 검증 확인 필요 | C6: =IF(LENB(TRIM(데이터!N7))=0,"",IF(ISERROR(VLOOKUP(데이터!N7,코드!$B$2:$B$7,1,0)),"데이터!N7 코드값을 잘못입력하였습니다!","")) | D6: =IF(LENB(TRIM(데이터!O7))=0,"",IF(ISERROR(VLOOKUP(데이터!O7,코드!$C$2:$C$7,1,0)),"데이터!O7 코드값을 잘못입력하였습니다!","")) | E6: =IF(LENB(TRIM(데이터!P7))=0,"",IF(ISERROR(VLOOKUP(데이터!P7,코드!$D$2:$D$47,1,0)),"데이터!P7 코드값을 잘못입력하였습니다!","")) -> 데이터!P7 코드값을 잘못입력하였습니다! | F6: =IF(LENB(TRIM(데이터!Q7))=0,"",IF(ISERROR(VLOOKUP(데이터!Q7,코드!$E$2:$E$13158,1,0)),"데이터!Q7 코드값을 잘못입력하였습니다!","")) | G6: =IF(LENB(TRIM(데이터!R7))=0,"",IF(ISERROR(VLOOKUP(데이터!R7,코드!$E$2:$E$13158,1,0)),"데이터!R7 코드값을 잘못입력하였습니다!","")) | H6: =IF(LENB(TRIM(데이터!S7))=0,"",IF(ISERROR(VLOOKUP(데이터!S7,코드!$D$2:$D$47,1,0)),"데이터!S7 코드값을 잘못입력하였습니다!","")) | I6: =IF(LENB(TRIM(데이터!T7))=0,"",IF(ISERROR(VLOOKUP(데이터!T7,코드!$E$2:$E$13158,1,0)),"데이터!T7 코드값을 잘못입력하였습니다!","")) | J6: =IF(LENB(TRIM(데이터!U7))=0,"",IF(ISERROR(VLOOKUP(데이터!U7,코드!$E$2:$E$13158,1,0)),"데이터!U7 코드값을 잘못입력하였습니다!","")) | K6: =IF(LENB(TRIM(데이터!V7))=0,"",IF(ISERROR(VLOOKUP(데이터!V7,코드!$F$2:$F$4,1,0)),"데이터!V7 코드값을 잘못입력하였습니다!","")) | L6: =IF(LENB(TRIM(데이터!W7))=0,"",IF(ISERROR(VLOOKUP(데이터!W7,코드!$F$2:$F$4,1,0)),"데이터!W7 코드값을 잘못입력하였습니다!","")) | M6: =IF(LENB(TRIM(데이터!X7))=0,"",IF(ISERROR(VLOOKUP(데이터!X7,코드!$F$2:$F$4,1,0)),"데이터!X7 코드값을 잘못입력하였습니다!","")) | N6: =IF(LENB(TRIM(데이터!Y7))=0,"",IF(ISERROR(VLOOKUP(데이터!Y7,코드!$F$2:$F$4,1,0)),"데이터!Y7 코드값을 잘못입력하였습니다!","")) | O6: =IF(LENB(TRIM(데이터!AO7))=0,"",IF(ISERROR(VLOOKUP(데이터!AO7,코드!$G$2:$G$29,1,0)),"데이터!AO7 코드값을 잘못입력하였습니다!","")) | P6: =IF(LENB(TRIM(데이터!AS7))=0,"",IF(ISERROR(VLOOKUP(데이터!AS7,코드!$H$2:$H$5,1,0)),"데이터!AS7 코드값을 잘못입력하였습니다!","")) | Q6: =IF(LENB(TRIM(데이터!AT7))=0,"",IF(ISERROR(VLOOKUP(데이터!AT7,코드!$I$2:$I$6,1,0)),"데이터!AT7 코드값을 잘못입력하였습니다!","")) | R6: =IF(LENB(TRIM(데이터!AV7))=0,"",IF(ISERROR(VLOOKUP(데이터!AV7,코드!$J$2:$J$8,1,0)),"데이터!AV7 코드값을 잘못입력하였습니다!","")) | S6: =IF(LENB(TRIM(데이터!AW7))=0,"",IF(ISERROR(VLOOKUP(데이터!AW7,코드!$K$2:$K$19,1,0)),"데이터!AW7 코드값을 잘못입력하였습니다!",""))
A7: =IF(COUNTIF(B7:S7,"*!"),COUNTIF(B7:S7,"*!")&"건 이상 검증 확인 필요","") -> 1건 이상 검증 확인 필요 | C7: =IF(LENB(TRIM(데이터!N8))=0,"",IF(ISERROR(VLOOKUP(데이터!N8,코드!$B$2:$B$7,1,0)),"데이터!N8 코드값을 잘못입력하였습니다!","")) | D7: =IF(LENB(TRIM(데이터!O8))=0,"",IF(ISERROR(VLOOKUP(데이터!O8,코드!$C$2:$C$7,1,0)),"데이터!O8 코드값을 잘못입력하였습니다!","")) | E7: =IF(LENB(TRIM(데이터!P8))=0,"",IF(ISERROR(VLOOKUP(데이터!P8,코드!$D$2:$D$47,1,0)),"데이터!P8 코드값을 잘못입력하였습니다!","")) -> 데이터!P8 코드값을 잘못입력하였습니다! | F7: =IF(LENB(TRIM(데이터!Q8))=0,"",IF(ISERROR(VLOOKUP(데이터!Q8,코드!$E$2:$E$13158,1,0)),"데이터!Q8 코드값을 잘못입력하였습니다!","")) | G7: =IF(LENB(TRIM(데이터!R8))=0,"",IF(ISERROR(VLOOKUP(데이터!R8,코드!$E$2:$E$13158,1,0)),"데이터!R8 코드값을 잘못입력하였습니다!","")) | H7: =IF(LENB(TRIM(데이터!S8))=0,"",IF(ISERROR(VLOOKUP(데이터!S8,코드!$D$2:$D$47,1,0)),"데이터!S8 코드값을 잘못입력하였습니다!","")) | I7: =IF(LENB(TRIM(데이터!T8))=0,"",IF(ISERROR(VLOOKUP(데이터!T8,코드!$E$2:$E$13158,1,0)),"데이터!T8 코드값을 잘못입력하였습니다!","")) | J7: =IF(LENB(TRIM(데이터!U8))=0,"",IF(ISERROR(VLOOKUP(데이터!U8,코드!$E$2:$E$13158,1,0)),"데이터!U8 코드값을 잘못입력하였습니다!","")) | K7: =IF(LENB(TRIM(데이터!V8))=0,"",IF(ISERROR(VLOOKUP(데이터!V8,코드!$F$2:$F$4,1,0)),"데이터!V8 코드값을 잘못입력하였습니다!","")) | L7: =IF(LENB(TRIM(데이터!W8))=0,"",IF(ISERROR(VLOOKUP(데이터!W8,코드!$F$2:$F$4,1,0)),"데이터!W8 코드값을 잘못입력하였습니다!","")) | M7: =IF(LENB(TRIM(데이터!X8))=0,"",IF(ISERROR(VLOOKUP(데이터!X8,코드!$F$2:$F$4,1,0)),"데이터!X8 코드값을 잘못입력하였습니다!","")) | N7: =IF(LENB(TRIM(데이터!Y8))=0,"",IF(ISERROR(VLOOKUP(데이터!Y8,코드!$F$2:$F$4,1,0)),"데이터!Y8 코드값을 잘못입력하였습니다!","")) | O7: =IF(LENB(TRIM(데이터!AO8))=0,"",IF(ISERROR(VLOOKUP(데이터!AO8,코드!$G$2:$G$29,1,0)),"데이터!AO8 코드값을 잘못입력하였습니다!","")) | P7: =IF(LENB(TRIM(데이터!AS8))=0,"",IF(ISERROR(VLOOKUP(데이터!AS8,코드!$H$2:$H$5,1,0)),"데이터!AS8 코드값을 잘못입력하였습니다!","")) | Q7: =IF(LENB(TRIM(데이터!AT8))=0,"",IF(ISERROR(VLOOKUP(데이터!AT8,코드!$I$2:$I$6,1,0)),"데이터!AT8 코드값을 잘못입력하였습니다!","")) | R7: =IF(LENB(TRIM(데이터!AV8))=0,"",IF(ISERROR(VLOOKUP(데이터!AV8,코드!$J$2:$J$8,1,0)),"데이터!AV8 코드값을 잘못입력하였습니다!","")) | S7: =IF(LENB(TRIM(데이터!AW8))=0,"",IF(ISERROR(VLOOKUP(데이터!AW8,코드!$K$2:$K$19,1,0)),"데이터!AW8 코드값을 잘못입력하였습니다!",""))
A8: =IF(COUNTIF(B8:S8,"*!"),COUNTIF(B8:S8,"*!")&"건 이상 검증 확인 필요","") -> 1건 이상 검증 확인 필요 | C8: =IF(LENB(TRIM(데이터!N9))=0,"",IF(ISERROR(VLOOKUP(데이터!N9,코드!$B$2:$B$7,1,0)),"데이터!N9 코드값을 잘못입력하였습니다!","")) | D8: =IF(LENB(TRIM(데이터!O9))=0,"",IF(ISERROR(VLOOKUP(데이터!O9,코드!$C$2:$C$7,1,0)),"데이터!O9 코드값을 잘못입력하였습니다!","")) | E8: =IF(LENB(TRIM(데이터!P9))=0,"",IF(ISERROR(VLOOKUP(데이터!P9,코드!$D$2:$D$47,1,0)),"데이터!P9 코드값을 잘못입력하였습니다!","")) -> 데이터!P9 코드값을 잘못입력하였습니다! | F8: =IF(LENB(TRIM(데이터!Q9))=0,"",IF(ISERROR(VLOOKUP(데이터!Q9,코드!$E$2:$E$13158,1,0)),"데이터!Q9 코드값을 잘못입력하였습니다!","")) | G8: =IF(LENB(TRIM(데이터!R9))=0,"",IF(ISERROR(VLOOKUP(데이터!R9,코드!$E$2:$E$13158,1,0)),"데이터!R9 코드값을 잘못입력하였습니다!","")) | H8: =IF(LENB(TRIM(데이터!S9))=0,"",IF(ISERROR(VLOOKUP(데이터!S9,코드!$D$2:$D$47,1,0)),"데이터!S9 코드값을 잘못입력하였습니다!","")) | I8: =IF(LENB(TRIM(데이터!T9))=0,"",IF(ISERROR(VLOOKUP(데이터!T9,코드!$E$2:$E$13158,1,0)),"데이터!T9 코드값을 잘못입력하였습니다!","")) | J8: =IF(LENB(TRIM(데이터!U9))=0,"",IF(ISERROR(VLOOKUP(데이터!U9,코드!$E$2:$E$13158,1,0)),"데이터!U9 코드값을 잘못입력하였습니다!","")) | K8: =IF(LENB(TRIM(데이터!V9))=0,"",IF(ISERROR(VLOOKUP(데이터!V9,코드!$F$2:$F$4,1,0)),"데이터!V9 코드값을 잘못입력하였습니다!","")) | L8: =IF(LENB(TRIM(데이터!W9))=0,"",IF(ISERROR(VLOOKUP(데이터!W9,코드!$F$2:$F$4,1,0)),"데이터!W9 코드값을 잘못입력하였습니다!","")) | M8: =IF(LENB(TRIM(데이터!X9))=0,"",IF(ISERROR(VLOOKUP(데이터!X9,코드!$F$2:$F$4,1,0)),"데이터!X9 코드값을 잘못입력하였습니다!","")) | N8: =IF(LENB(TRIM(데이터!Y9))=0,"",IF(ISERROR(VLOOKUP(데이터!Y9,코드!$F$2:$F$4,1,0)),"데이터!Y9 코드값을 잘못입력하였습니다!","")) | O8: =IF(LENB(TRIM(데이터!AO9))=0,"",IF(ISERROR(VLOOKUP(데이터!AO9,코드!$G$2:$G$29,1,0)),"데이터!AO9 코드값을 잘못입력하였습니다!","")) | P8: =IF(LENB(TRIM(데이터!AS9))=0,"",IF(ISERROR(VLOOKUP(데이터!AS9,코드!$H$2:$H$5,1,0)),"데이터!AS9 코드값을 잘못입력하였습니다!","")) | Q8: =IF(LENB(TRIM(데이터!AT9))=0,"",IF(ISERROR(VLOOKUP(데이터!AT9,코드!$I$2:$I$6,1,0)),"데이터!AT9 코드값을 잘못입력하였습니다!","")) | R8: =IF(LENB(TRIM(데이터!AV9))=0,"",IF(ISERROR(VLOOKUP(데이터!AV9,코드!$J$2:$J$8,1,0)),"데이터!AV9 코드값을 잘못입력하였습니다!","")) | S8: =IF(LENB(TRIM(데이터!AW9))=0,"",IF(ISERROR(VLOOKUP(데이터!AW9,코드!$K$2:$K$19,1,0)),"데이터!AW9 코드값을 잘못입력하였습니다!",""))
A9: =IF(COUNTIF(B9:S9,"*!"),COUNTIF(B9:S9,"*!")&"건 이상 검증 확인 필요","") -> 1건 이상 검증 확인 필요 | C9: =IF(LENB(TRIM(데이터!N10))=0,"",IF(ISERROR(VLOOKUP(데이터!N10,코드!$B$2:$B$7,1,0)),"데이터!N10 코드값을 잘못입력하였습니다!","")) | D9: =IF(LENB(TRIM(데이터!O10))=0,"",IF(ISERROR(VLOOKUP(데이터!O10,코드!$C$2:$C$7,1,0)),"데이터!O10 코드값을 잘못입력하였습니다!","")) | E9: =IF(LENB(TRIM(데이터!P10))=0,"",IF(ISERROR(VLOOKUP(데이터!P10,코드!$D$2:$D$47,1,0)),"데이터!P10 코드값을 잘못입력하였습니다!","")) -> 데이터!P10 코드값을 잘못입력하였습니다! | F9: =IF(LENB(TRIM(데이터!Q10))=0,"",IF(ISERROR(VLOOKUP(데이터!Q10,코드!$E$2:$E$13158,1,0)),"데이터!Q10 코드값을 잘못입력하였습니다!","")) | G9: =IF(LENB(TRIM(데이터!R10))=0,"",IF(ISERROR(VLOOKUP(데이터!R10,코드!$E$2:$E$13158,1,0)),"데이터!R10 코드값을 잘못입력하였습니다!","")) | H9: =IF(LENB(TRIM(데이터!S10))=0,"",IF(ISERROR(VLOOKUP(데이터!S10,코드!$D$2:$D$47,1,0)),"데이터!S10 코드값을 잘못입력하였습니다!","")) | I9: =IF(LENB(TRIM(데이터!T10))=0,"",IF(ISERROR(VLOOKUP(데이터!T10,코드!$E$2:$E$13158,1,0)),"데이터!T10 코드값을 잘못입력하였습니다!","")) | J9: =IF(LENB(TRIM(데이터!U10))=0,"",IF(ISERROR(VLOOKUP(데이터!U10,코드!$E$2:$E$13158,1,0)),"데이터!U10 코드값을 잘못입력하였습니다!","")) | K9: =IF(LENB(TRIM(데이터!V10))=0,"",IF(ISERROR(VLOOKUP(데이터!V10,코드!$F$2:$F$4,1,0)),"데이터!V10 코드값을 잘못입력하였습니다!","")) | L9: =IF(LENB(TRIM(데이터!W10))=0,"",IF(ISERROR(VLOOKUP(데이터!W10,코드!$F$2:$F$4,1,0)),"데이터!W10 코드값을 잘못입력하였습니다!","")) | M9: =IF(LENB(TRIM(데이터!X10))=0,"",IF(ISERROR(VLOOKUP(데이터!X10,코드!$F$2:$F$4,1,0)),"데이터!X10 코드값을 잘못입력하였습니다!","")) | N9: =IF(LENB(TRIM(데이터!Y10))=0,"",IF(ISERROR(VLOOKUP(데이터!Y10,코드!$F$2:$F$4,1,0)),"데이터!Y10 코드값을 잘못입력하였습니다!","")) | O9: =IF(LENB(TRIM(데이터!AO10))=0,"",IF(ISERROR(VLOOKUP(데이터!AO10,코드!$G$2:$G$29,1,0)),"데이터!AO10 코드값을 잘못입력하였습니다!","")) | P9: =IF(LENB(TRIM(데이터!AS10))=0,"",IF(ISERROR(VLOOKUP(데이터!AS10,코드!$H$2:$H$5,1,0)),"데이터!AS10 코드값을 잘못입력하였습니다!","")) | Q9: =IF(LENB(TRIM(데이터!AT10))=0,"",IF(ISERROR(VLOOKUP(데이터!AT10,코드!$I$2:$I$6,1,0)),"데이터!AT10 코드값을 잘못입력하였습니다!","")) | R9: =IF(LENB(TRIM(데이터!AV10))=0,"",IF(ISERROR(VLOOKUP(데이터!AV10,코드!$J$2:$J$8,1,0)),"데이터!AV10 코드값을 잘못입력하였습니다!","")) | S9: =IF(LENB(TRIM(데이터!AW10))=0,"",IF(ISERROR(VLOOKUP(데이터!AW10,코드!$K$2:$K$19,1,0)),"데이터!AW10 코드값을 잘못입력하였습니다!",""))
A10: =IF(COUNTIF(B10:S10,"*!"),COUNTIF(B10:S10,"*!")&"건 이상 검증 확인 필요","") -> 2건 이상 검증 확인 필요 | C10: =IF(LENB(TRIM(데이터!N11))=0,"",IF(ISERROR(VLOOKUP(데이터!N11,코드!$B$2:$B$7,1,0)),"데이터!N11 코드값을 잘못입력하였습니다!","")) | D10: =IF(LENB(TRIM(데이터!O11))=0,"",IF(ISERROR(VLOOKUP(데이터!O11,코드!$C$2:$C$7,1,0)),"데이터!O11 코드값을 잘못입력하였습니다!","")) | E10: =IF(LENB(TRIM(데이터!P11))=0,"",IF(ISERROR(VLOOKUP(데이터!P11,코드!$D$2:$D$47,1,0)),"데이터!P11 코드값을 잘못입력하였습니다!","")) -> 데이터!P11 코드값을 잘못입력하였습니다! | F10: =IF(LENB(TRIM(데이터!Q11))=0,"",IF(ISERROR(VLOOKUP(데이터!Q11,코드!$E$2:$E$13158,1,0)),"데이터!Q11 코드값을 잘못입력하였습니다!","")) | G10: =IF(LENB(TRIM(데이터!R11))=0,"",IF(ISERROR(VLOOKUP(데이터!R11,코드!$E$2:$E$13158,1,0)),"데이터!R11 코드값을 잘못입력하였습니다!","")) | H10: =IF(LENB(TRIM(데이터!S11))=0,"",IF(ISERROR(VLOOKUP(데이터!S11,코드!$D$2:$D$47,1,0)),"데이터!S11 코드값을 잘못입력하였습니다!","")) -> 데이터!S11 코드값을 잘못입력하였습니다! | I10: =IF(LENB(TRIM(데이터!T11))=0,"",IF(ISERROR(VLOOKUP(데이터!T11,코드!$E$2:$E$13158,1,0)),"데이터!T11 코드값을 잘못입력하였습니다!","")) | J10: =IF(LENB(TRIM(데이터!U11))=0,"",IF(ISERROR(VLOOKUP(데이터!U11,코드!$E$2:$E$13158,1,0)),"데이터!U11 코드값을 잘못입력하였습니다!","")) | K10: =IF(LENB(TRIM(데이터!V11))=0,"",IF(ISERROR(VLOOKUP(데이터!V11,코드!$F$2:$F$4,1,0)),"데이터!V11 코드값을 잘못입력하였습니다!","")) | L10: =IF(LENB(TRIM(데이터!W11))=0,"",IF(ISERROR(VLOOKUP(데이터!W11,코드!$F$2:$F$4,1,0)),"데이터!W11 코드값을 잘못입력하였습니다!","")) | M10: =IF(LENB(TRIM(데이터!X11))=0,"",IF(ISERROR(VLOOKUP(데이터!X11,코드!$F$2:$F$4,1,0)),"데이터!X11 코드값을 잘못입력하였습니다!","")) | N10: =IF(LENB(TRIM(데이터!Y11))=0,"",IF(ISERROR(VLOOKUP(데이터!Y11,코드!$F$2:$F$4,1,0)),"데이터!Y11 코드값을 잘못입력하였습니다!","")) | O10: =IF(LENB(TRIM(데이터!AO11))=0,"",IF(ISERROR(VLOOKUP(데이터!AO11,코드!$G$2:$G$29,1,0)),"데이터!AO11 코드값을 잘못입력하였습니다!","")) | P10: =IF(LENB(TRIM(데이터!AS11))=0,"",IF(ISERROR(VLOOKUP(데이터!AS11,코드!$H$2:$H$5,1,0)),"데이터!AS11 코드값을 잘못입력하였습니다!","")) | Q10: =IF(LENB(TRIM(데이터!AT11))=0,"",IF(ISERROR(VLOOKUP(데이터!AT11,코드!$I$2:$I$6,1,0)),"데이터!AT11 코드값을 잘못입력하였습니다!","")) | R10: =IF(LENB(TRIM(데이터!AV11))=0,"",IF(ISERROR(VLOOKUP(데이터!AV11,코드!$J$2:$J$8,1,0)),"데이터!AV11 코드값을 잘못입력하였습니다!","")) | S10: =IF(LENB(TRIM(데이터!AW11))=0,"",IF(ISERROR(VLOOKUP(데이터!AW11,코드!$K$2:$K$19,1,0)),"데이터!AW11 코드값을 잘못입력하였습니다!",""))
A11: =IF(COUNTIF(B11:S11,"*!"),COUNTIF(B11:S11,"*!")&"건 이상 검증 확인 필요","") -> 1건 이상 검증 확인 필요 | C11: =IF(LENB(TRIM(데이터!N12))=0,"",IF(ISERROR(VLOOKUP(데이터!N12,코드!$B$2:$B$7,1,0)),"데이터!N12 코드값을 잘못입력하였습니다!","")) | D11: =IF(LENB(TRIM(데이터!O12))=0,"",IF(ISERROR(VLOOKUP(데이터!O12,코드!$C$2:$C$7,1,0)),"데이터!O12 코드값을 잘못입력하였습니다!","")) | E11: =IF(LENB(TRIM(데이터!P12))=0,"",IF(ISERROR(VLOOKUP(데이터!P12,코드!$D$2:$D$47,1,0)),"데이터!P12 코드값을 잘못입력하였습니다!","")) -> 데이터!P12 코드값을 잘못입력하였습니다! | F11: =IF(LENB(TRIM(데이터!Q12))=0,"",IF(ISERROR(VLOOKUP(데이터!Q12,코드!$E$2:$E$13158,1,0)),"데이터!Q12 코드값을 잘못입력하였습니다!","")) | G11: =IF(LENB(TRIM(데이터!R12))=0,"",IF(ISERROR(VLOOKUP(데이터!R12,코드!$E$2:$E$13158,1,0)),"데이터!R12 코드값을 잘못입력하였습니다!","")) | H11: =IF(LENB(TRIM(데이터!S12))=0,"",IF(ISERROR(VLOOKUP(데이터!S12,코드!$D$2:$D$47,1,0)),"데이터!S12 코드값을 잘못입력하였습니다!","")) | I11: =IF(LENB(TRIM(데이터!T12))=0,"",IF(ISERROR(VLOOKUP(데이터!T12,코드!$E$2:$E$13158,1,0)),"데이터!T12 코드값을 잘못입력하였습니다!","")) | J11: =IF(LENB(TRIM(데이터!U12))=0,"",IF(ISERROR(VLOOKUP(데이터!U12,코드!$E$2:$E$13158,1,0)),"데이터!U12 코드값을 잘못입력하였습니다!","")) | K11: =IF(LENB(TRIM(데이터!V12))=0,"",IF(ISERROR(VLOOKUP(데이터!V12,코드!$F$2:$F$4,1,0)),"데이터!V12 코드값을 잘못입력하였습니다!","")) | L11: =IF(LENB(TRIM(데이터!W12))=0,"",IF(ISERROR(VLOOKUP(데이터!W12,코드!$F$2:$F$4,1,0)),"데이터!W12 코드값을 잘못입력하였습니다!","")) | M11: =IF(LENB(TRIM(데이터!X12))=0,"",IF(ISERROR(VLOOKUP(데이터!X12,코드!$F$2:$F$4,1,0)),"데이터!X12 코드값을 잘못입력하였습니다!","")) | N11: =IF(LENB(TRIM(데이터!Y12))=0,"",IF(ISERROR(VLOOKUP(데이터!Y12,코드!$F$2:$F$4,1,0)),"데이터!Y12 코드값을 잘못입력하였습니다!","")) | O11: =IF(LENB(TRIM(데이터!AO12))=0,"",IF(ISERROR(VLOOKUP(데이터!AO12,코드!$G$2:$G$29,1,0)),"데이터!AO12 코드값을 잘못입력하였습니다!","")) | P11: =IF(LENB(TRIM(데이터!AS12))=0,"",IF(ISERROR(VLOOKUP(데이터!AS12,코드!$H$2:$H$5,1,0)),"데이터!AS12 코드값을 잘못입력하였습니다!","")) | Q11: =IF(LENB(TRIM(데이터!AT12))=0,"",IF(ISERROR(VLOOKUP(데이터!AT12,코드!$I$2:$I$6,1,0)),"데이터!AT12 코드값을 잘못입력하였습니다!","")) | R11: =IF(LENB(TRIM(데이터!AV12))=0,"",IF(ISERROR(VLOOKUP(데이터!AV12,코드!$J$2:$J$8,1,0)),"데이터!AV12 코드값을 잘못입력하였습니다!","")) | S11: =IF(LENB(TRIM(데이터!AW12))=0,"",IF(ISERROR(VLOOKUP(데이터!AW12,코드!$K$2:$K$19,1,0)),"데이터!AW12 코드값을 잘못입력하였습니다!",""))

Sheet 데이터백업
A1: {"조건절":"Y","DB테이블명":"EGENE.ESO_CM","컬럼명":"CM_ID"} | B1: {"조건절":"N","DB테이블명":"EGENE.ESO_CM","컬럼명":"CM_NAME"} | C1: {"조건절":"N","DB테이블명":"EGENE.ESO_CM","컬럼명":"CM_TCM_ID"} | D1: {"조건절":"N","DB테이블명":"EGENE.ESO_CM","컬럼명":"CM_IP"} | E1: {"조건절":"N","DB테이블명":"","컬럼명":""} | F1: {"조건절":"N","DB테이블명":"","컬럼명":""} | G1: {"조건절":"N","DB테이블명":"EGENE.ESO_CM","컬럼명":"CM_SVR_CAT_CD"} | H1: {"조건절":"N","DB테이블명":"","컬럼명":""} | I1: {"조건절":"N","DB테이블명":"EGENE.ESO_CM","컬럼명":"CM_CAT_CD"} | J1: {"조건절":"N","DB테이블명":"EGENE.ESO_CM","컬럼명":"CM_DESC"} | K1: {"조건절":"N","DB테이블명":"EGENE.ESO_CM","컬럼명":"CM_PID"} | L1: {"조건절":"N","DB테이블명":"EGENE.ESO_CM","컬럼명":"CM_ICM_WOG_ID"} | M1: {"조건절":"N","DB테이블명":"EGENE.ESO_CM","컬럼명":"CM_ICM_SEV_GRADE"} | N1: {"조건절":"N","DB테이블명":"EGENE.ESO_CM","컬럼명":"CM_LOCATION"} | O1: {"조건절":"N","DB테이블명":"EGENE.ESO_CM","컬럼명":"CM_FLOOR"} | P1: {"조건절":"N","DB테이블명":"EGENE.ESO_CM","컬럼명":"CM_MGR_DPT_ID"} | Q1: {"조건절":"N","DB테이블명":"EGENE.ESO_CM","컬럼명":"CM_MGR_EMP_ID"} | R1: {"조건절":"N","DB테이블명":"EGENE.ESO_CM","컬럼명":"CM_MGS_EMP_ID"} | S1: {"조건절":"N","DB테이블명":"EGENE.ESO_CM","컬럼명":"CM_OP_DPT_ID"} | T1: {"조건절":"N","DB테이블명":"EGENE.ESO_CM","컬럼명":"CM_OP_EMP_ID"} | U1: {"조건절":"N","DB테이블명":"EGENE.ESO_CM","컬럼명":"CM_OPS_EMP_ID"} | V1: {"조건절":"N","DB테이블명":"EGENE.ESO_CM","컬럼명":"CM_PCM_YN"} | W1: {"조건절":"N","DB테이블명":"EGENE.ESO_CM","컬럼명":"CM_PCM_PERIOD_YN"} | X1: {"조건절":"N","DB테이블명":"EGENE.ESO_CM","컬럼명":"CM_PCM_PLANSTOP_YN"} | Y1: {"조건절":"N","DB테이블명":"EGENE.ESO_CM","컬럼명":"CM_PCM_UNPERIOD_YN"} | Z1: {"조건절":"N","DB테이블명":"EGENE.ESO_CM","컬럼명":"CM_PCM_WOG_ID"} | AA1: {"조건절":"N","DB테이블명":"EGENE.ESO_CM","컬럼명":"CM_SVR_SER_NUM"} | AB1: {"조건절":"N","DB테이블명":"EGENE.ESO_CM","컬럼명":"CM_CTR_NUM"} | AC1: {"조건절":"N","DB테이블명":"EGENE.ESO_CM","컬럼명":"CM_SVR_CLA_NUM"} | AD1: {"조건절":"N","DB테이블명":"EGENE.ESO_CM","컬럼명":"CM_AST_NUM"} | AE1: {"조건절":"N","DB테이블명":"EGENE.ESO_CM","컬럼명":"CM_MODEL_NAME"} | AF1: {"조건절":"N","DB테이블명":"EGENE.ESO_CM","컬럼명":"CM_RACK_NUM"} | AG1: {"조건절":"N","DB테이블명":"EGENE.ESO_CM","컬럼명":"CM_OS"} | AH1: {"조건절":"N","DB테이블명":"EGENE.ESO_CM","컬럼명":"CM_OS_VERSION"} | AI1: {"조건절":"N","DB테이블명":"EGENE.ESO_CM","컬럼명":"CM_SYSMON_SOLUTION"} | AJ1: {"조건절":"N","DB테이블명":"EGENE.ESO_CM","컬럼명":"CM_OS_PATCH"} | AK1: {"조건절":"N","DB테이블명":"EGENE.ESO_CM","컬럼명":"CM_MAKE제조사"} | AL1: {"조건절":"N","DB테이블명":"EGENE.ESO_CM","컬럼명":"CM_CPU_NUM"} | AM1: {"조건절":"N","DB테이블명":"EGENE.ESO_CM","컬럼명":"CM_CPU_CORE_NUM"} | AN1: {"조건절":"N","DB테이블명":"EGENE.ESO_CM","컬럼명":"CM_CPU_SPEED"} | AO1: {"조건절":"N","DB테이블명":"EGENE.ESO_CM","컬럼명":"CM_CPU_TYPE"} | AP1: {"조건절":"N","DB테이블명":"EGENE.ESO_CM","컬럼명":"CM_TPMC"} | AQ1: {"조건절":"N","DB테이블명":"EGENE.ESO_CM","컬럼명":"CM_MEMORY"} | AR1: {"조건절":"N","DB테이블명":"EGENE.ESO_CM","컬럼명":"CM_IN_DISK"} | AS1: {"조건절":"N","DB테이블명":"EGENE.ESO_CM","컬럼명":"CM_NET_CAT_CD"} | AT1: {"조건절":"N","DB테이블명":"EGENE.ESO_CM","컬럼명":"CM_NET_SPEED"} | AU1: {"조건절":"N","DB테이블명":"EGENE.ESO_CM","컬럼명":"CM_NET_IP"} | AV1: {"조건절":"N","DB테이블명":"EGENE.ESO_CM","컬럼명":"CM_SVC_CAT_CD"} | AW1: {"조건절":"N","DB테이블명":"EGENE.ESO_CM","컬럼명":"CM_SVR_CLA_CD"} | AX1: {"조건절":"N","DB테이블명":"EGENE.ESO_CM","컬럼명":"CM_APP"} | AY1: {"조건절":"N","DB테이블명":"EGENE.ESO_CM","컬럼명":"CM_BIZ_NAME"} | AZ1: {"조건절":"N","DB테이블명":"EGENE.ESO_CM","컬럼명":"CM_BIZ_NAME_DESC"} | BA1: {"조건절":"N","DB테이블명":"EGENE.ESO_CM","컬럼명":"CM_VIR_SOLUTION"} | BB1: {"조건절":"N","DB테이블명":"EGENE.ESO_CM","컬럼명":"CM_DR_SOLUTION"} | BC1: {"조건절":"N","DB테이블명":"EGENE.ESO_CM","컬럼명":"CM_BAK_SOLUTION"} | BD1: {"조건절":"N","DB테이블명":"EGENE.ESO_CM","컬럼명":"CM_SVC_TIME"} | BE1: {"조건절":"N","DB테이블명":"EGENE.ESO_CM","컬럼명":"CM_SUPPLY"} | BF1: {"조건절":"N","DB테이블명":"EGENE.ESO_CM","컬럼명":"CM_SVR_CARD"} | BG1: {"조건절":"N","DB테이블명":"EGENE.ESO_CM","컬럼명":"CM_INFO_ETC"} | BH1: {"조건절":"N","DB테이블명":"EGENE.ESO_CM","컬럼명":"CM_SVR_ETC"} | BI1: {"조건절":"N","DB테이블명":"EGENE.ESO_CM","컬럼명":"CM_MOD_EMP_ID"} | BJ1: {"조건절":"N","DB테이블명":"EGENE.ESO_CM","컬럼명":"CM_MOD_DTTM"}
A2: 구성ID | B2: 구성항목명 | C2: 현행화ID | D2: IP | E2: AD비교 | F2: AD_VERSION | G2: 장비구분 | H2: 항목명중복건수 | I2: 서버구분 | J2: 구성항목명 | K2: 구성항목설명 | L2: 인시던트처리직무 | M2: 인시던트심각도 | N2: 설치지역 | O2: 설치층수 | P2: 관리부서 | Q2: 관리직원(정) | R2: 관리직원(부) | S2: 운영부서 | T2: 운영직원(정) | U2: 운영직원(부) | V2: 예방점검대상유무 | W2: 예방점검대상유무 | X2: 정기점검대상여부 | Y2: 계획정지대상여부 | Z2: 특별점검대상여부 | AA2: 서버관리번호 | AB2: 계약번호 | AC2: 물품분류번호 | AD2: 물품번호 | AE2: 모델명 | AF2: Rack번호 | AG2: 운영체제 | AH2: 운영체제버전 | AI2: 운영체제관리툴명 | AJ2: 운영체제패치버전 | AK2: 제조사 | AL2: CPU수 | AM2: CORE수(물리/논리) | AN2: CPU속도(GHz) | AO2: CPU타입 | AP2: CPU_TPMC | AQ2: 메모리용량(GB) | AR2: 내장디스크용량(GB) | AS2: 네트워크방식 | AT2: 네트워크속도 | AU2: 네트워크IP주소 | AV2: 가동구분 | AW2: 서버분류 | AX2: 어플리케이션코드 | AY2: 업무명 | AZ2: 상세업무명 | BA2: 가상화솔루션명 | BB2: 재해복구솔루션명 | BC2: 백업솔루션명 | BD2: 서비스제공시간 | BE2: 공급사 | BF2: 서버Card정보 | BG2: 구성정보비고 | BH2: 관리정보비고 | BI2: 수정자 | BJ2: 수정일시
A3: CM2009-000051 | B3: begapd01 | C3: BEGAPD01_10.38.137.61 | D3: 10.38.137.61 | H3: 0 | I3: 서버논리|KBCMCAT03002 | J3: begapd01 | K3: 서울ROC 통합정보 AP 개발 | L3: 서버OS(LINUX계열)|SWA00073_SSM | M3: 5|KBCMSEVGD05 | N3: 여의도센터|KBCMLOCATION002 | P3: 시스템운영부|103640 | Q3: 인프라시스템부(P) 양동민|5492242 | R3: 인프라시스템부(P) 안정은|2855831 | V3: 아니요|0 | W3: 아니요|0 | X3: 아니요|0 | Y3: 아니요|0 | Z3: 아니요|0 | AG3: Linux | AH3: Red Hat Enterprise Linux Server release 7.6 (Maipo) | AK3: VMware, Inc. | AL3: 2 | AM3: 2/2 | AN3: 2.4 | AQ3: 31 | AR3: 306 | BH3: LINUX | BJ3: 20220409152539
A4: CM2009-000052 | B4: begapo01 | C4: BEGAPO01_10.37.37.61 | D4: 10.37.37.61 | H4: 0 | I4: 서버논리|KBCMCAT03002 | J4: begapo01 | K4: 서울ROC 통합정보 AP | L4: 서버OS(LINUX계열)|SWA00073_SSM | M4: 3|KBCMSEVGD03 | N4: 김포센터|KBCMLOCATION001 | P4: 시스템운영부|103640 | Q4: 인프라시스템부(P) 양동민|5492242 | R4: 인프라시스템부(P) 안정은|2855831 | V4: 예|1 | W4: 예|1 | X4: 예|1 | Y4: 예|1 | Z4: 예|1 | AG4: Linux | AH4: Red Hat Enterprise Linux Server release 7.6 (Maipo) | AK4: VMware, Inc. | AL4: 4 | AM4: 4/4 | AN4: 2.4 | AQ4: 63 | AR4: 406 | BH4: LINUX | BJ4: 20210604110747
A5: CM2004-000581 | B5: begapo11 | C5: BEGAPO11_10.37.38.101 | D5: 10.37.38.101 | H5: 0 | I5: 서버논리|KBCMCAT03002 | J5: begapo11 | L5: 서버OS(LINUX계열)|SWA00073_SSM | M5: 3|KBCMSEVGD03 | N5: 김포센터|KBCMLOCATION001 | P5: 시스템운영부|103640 | Q5: 인프라시스템부(P) 양동민|5492242 | R5: 인프라시스템부(P) 안정은|2855831 | V5: 예|1 | W5: 예|1 | X5: 예|1 | Y5: 예|1 | Z5: 예|1 | AG5: Linux | AH5: Red Hat Enterprise Linux Server release 7.6 (Maipo) | AK5: HPE | AL5: 2 | AM5: 4/8 | AN5: 3.6 | AQ5: 31 | AR5: 22423 | BH5: LINUX | BJ5: 20210916083435
A6: CM2009-000053 | B6: begaps01 | C6: BEGAPS01_10.38.37.61 | D6: 10.38.37.61 | H6: 0 | I6: 서버논리|KBCMCAT03002 | J6: begaps01 | K6: 서울ROC 통합정보 AP 스테이징 | L6: 서버OS(LINUX계열)|SWA00073_SSM | M6: 5|KBCMSEVGD05 | N6: 여의도센터|KBCMLOCATION002 | P6: 시스템운영부|103640 | Q6: 인프라시스템부(P) 양동민|5492242 | R6: 인프라시스템부(P) 안정은|2855831 | V6: 아니요|0 | W6: 아니요|0 | X6: 아니요|0 | Y6: 아니요|0 | Z6: 아니요|0 | AG6: Linux | AH6: Red Hat Enterprise Linux Server release 7.6 (Maipo) | AK6: VMware, Inc. | AL6: 2 | AM6: 2/2 | AN6: 2.4 | AQ6: 31 | AR6: 306 | BH6: LINUX | BJ6: 20210604103702
A7: CM2009-000054 | B7: begdbd01 | C7: BEGDBD01_10.38.138.61 | D7: 10.38.138.61 | H7: 0 | I7: 서버논리|KBCMCAT03002 | J7: begdbd01 | K7: 서울ROC 통합정보DB | L7: 서버OS(LINUX계열)|SWA00073_SSM | M7: 5|KBCMSEVGD05 | N7: 여의도센터|KBCMLOCATION002 | P7: 시스템운영부|103640 | Q7: 인프라시스템부(P) 양동민|5492242 | R7: 인프라시스템부(P) 안정은|2855831 | V7: 아니요|0 | W7: 아니요|0 | X7: 아니요|0 | Y7: 아니요|0 | Z7: 아니요|0 | AG7: Linux | AH7: Red Hat Enterprise Linux Server release 7.6 (Maipo) | AK7: HPE | AL7: 2 | AM7: 2/2 | AN7: 3.6 | AQ7: 31 | AR7: 2690 | BH7: LINUX | BJ7: 20220409152539
A8: CM2009-000055 | B8: begdbo01 | C8: BEGDBO01_10.37.38.61 | D8: 10.37.38.61 | H8: 0 | I8: 서버논리|KBCMCAT03002 | J8: begdbo01 | K8: 서울ROC 통합정보DB | L8: 서버OS(LINUX계열)|SWA00073_SSM | M8: 3|KBCMSEVGD03 | N8: 김포센터|KBCMLOCATION001 | P8: 시스템운영부|103640 | Q8: 인프라시스템부(P) 양동민|5492242 | R8: 인프라시스템부(P) 안정은|2855831 | V8: 예|1 | W8: 예|1 | X8: 예|1 | Y8: 예|1 | Z8: 예|1 | AG8: Linux | AH8: Red Hat Enterprise Linux Server release 7.6 (Maipo) | AK8: HPE | AL8: 2 | AM8: 4/8 | AN8: 3.6 | AQ8: 62 | AR8: 19049 | BH8: LINUX | BJ8: 20210604110747
A9: CM2009-000056 | B9: begdbs01 | C9: BEGDBS01_10.38.38.61 | D9: 10.38.38.61 | H9: 0 | I9: 서버논리|KBCMCAT03002 | J9: begdbs01 | K9: 서울ROC 통합정보DB | L9: 서버OS(LINUX계열)|SWA00073_SSM | M9: 5|KBCMSEVGD05 | N9: 여의도센터|KBCMLOCATION002 | P9: 시스템운영부|103640 | Q9: 인프라시스템부(P) 양동민|5492242 | R9: 인프라시스템부(P) 안정은|2855831 | V9: 아니요|0 | W9: 아니요|0 | X9: 아니요|0 | Y9: 아니요|0 | Z9: 아니요|0 | AG9: Linux | AH9: Red Hat Enterprise Linux Server release 7.6 (Maipo) | AK9: HPE | AL9: 2 | AM9: 2/4 | AN9: 3.6 | AQ9: 31 | AR9: 17177 | BH9: LINUX | BJ9: 20210604103702
A10: CM2009-000057 | B10: belapd01 | C10: BELAPD01_10.38.137.51 | D10: 10.38.137.51 | H10: 0 | I10: 서버논리|KBCMCAT03002 | J10: belapd01 | K10: 서울ROC 정보AP | L10: 서버OS(LINUX계열)|SWA00073_SSM | M10: 5|KBCMSEVGD05 | N10: 여의도센터|KBCMLOCATION002 | P10: 시스템운영부|103640 | Q10: 인프라시스템부(P) 양동민|5492242 | R10: 인프라시스템부(P) 안정은|2855831 | V10: 아니요|0 | W10: 아니요|0 | X10: 아니요|0 | Y10: 아니요|0 | Z10: 아니요|0 | AG10: Linux | AH10: Red Hat Enterprise Linux Server release 7.6 (Maipo) | AK10: VMware, Inc. | AL10: 2 | AM10: 2/2 | AN10: 2.4 | AQ10: 31 | AR10: 306 | BH10: LINUX | BJ10: 20220409152539
A11: CM_SVR02744 | B11: belapd11 | C11: BELAPD11_10.38.131.12 | D11: 10.38.131.12 | H11: 0 | I11: 서버논리|KBCMCAT03002 | J11: belapd11 | L11: 서버OS(LINUX계열)|SWA00073_SSM | M11: 5|KBCMSEVGD05 | N11: 여의도센터|KBCMLOCATION002 | O11: 4|4 | P11: 시스템운영부|103640 | Q11: 인프라시스템부(P) 양동민|5492242 | R11: 인프라시스템부(P) 안정은|2855831 | S11: IT서비스개발부|125340 | T11: 글로벌플랫폼부(P) 이동윤|2829879 | V11: 아니요|0 | W11: 아니요|0 | X11: 아니요|0 | Y11: 아니요|0 | Z11: 아니요|0 | AA11: 3S4ZLX2 | AF11: 4F-A12-06 | AG11: Linux | AH11: Red Hat Enterprise Linux Server release 7.6 (Maipo) | AK11: VMware, Inc. | AL11: 5 | AM11: 5/5 | AN11: 2.6 | AP11: 0 | AQ11: 157 | AR11: 2354 | AW11: 정보성 업무 영업점 접점 서버|KBCMSVRCLA005 | AY11: 뉴욕AML AP 개발서버 | AZ11: 뉴욕AML AP 개발서버 | BA11: VMWare | BH11: LINUX | BJ11: 20210604103703
A12: CM2009-000058 | B12: belapo01 | C12: BELAPO01_10.37.37.51 | D12: 10.37.37.51 | H12: 0 | I12: 서버논리|KBCMCAT03002 | J12: belapo01 | K12: 서울ROC 정보AP | L12: 서버OS(LINUX계열)|SWA00073_SSM | M12: 3|KBCMSEVGD03 | N12: 김포센터|KBCMLOCATION001 | P12: 시스템운영부|103640 | Q12: 인프라시스템부(P) 양동민|5492242 | R12: 인프라시스템부(P) 안정은|2855831 | V12: 예|1 | W12: 예|1 | X12: 예|1 | Y12: 예|1 | Z12: 예|1 | AG12: Linux | AH12: Red Hat Enterprise Linux Server release 7.6 (Maipo) | AK12: VMware, Inc. | AL12: 2 | AM12: 2/2 | AN12: 2.4 | AQ12: 31 | AR12: 406 | BH12: LINUX | BJ12: 20210604110747

Sheet 수정된정보
A2: 데이터검증 | B2: 구성ID | C2: 구성항목명 | D2: 현행화ID | E2: IP | F2: AD비교 | G2: AD_VERSION | H2: 장비구분 | I2: 항목명중복건수 | J2: 서버구분 | K2: 구성항목명 | L2: 구성항목설명 | M2: 인시던트처리직무 | N2: 인시던트심각도 | O2: 설치지역 | P2: 설치층수 | Q2: 관리부서 | R2: 관리직원(정) | S2: 관리직원(부) | T2: 운영부서 | U2: 운영직원(정) | V2: 운영직원(부) | W2: 예방점검대상유무 | X2: 예방점검대상유무 | Y2: 정기점검대상여부 | Z2: 계획정지대상여부 | AA2: 특별점검대상여부 | AB2: 서버관리번호 | AC2: 계약번호 | AD2: 물품분류번호 | AE2: 물품번호 | AF2: 모델명 | AG2: Rack번호 | AH2: 운영체제 | AI2: 운영체제버전 | AJ2: 운영체제관리툴명 | AK2: 운영체제패치버전 | AL2: 제조사 | AM2: CPU수 | AN2: CORE수(물리/논리) | AO2: CPU속도(GHz) | AP2: CPU타입 | AQ2: CPU_TPMC | AR2: 메모리용량(GB) | AS2: 내장디스크용량(GB) | AT2: 네트워크방식 | AU2: 네트워크속도 | AV2: 네트워크IP주소 | AW2: 가동구분 | AX2: 서버분류 | AY2: 어플리케이션코드 | AZ2: 업무명 | BA2: 상세업무명 | BB2: 가상화솔루션명 | BC2: 재해복구솔루션명 | BD2: 백업솔루션명 | BE2: 서비스제공시간 | BF2: 공급사 | BG2: 서버Card정보 | BH2: 구성정보비고 | BI2: 관리정보비고 | BJ2: 수정자 | BK2: 수정일시
A3: =IF(COUNTIF(B3:BK3,"*->*") > 0,"수정","") | B3: =IF(데이터백업!A3=데이터!A3,"",데이터백업!A3&"->"&데이터!A3) | C3: =IF(데이터백업!B3=데이터!B3,"",데이터백업!B3&"->"&데이터!B3) | D3: =IF(데이터백업!C3=데이터!C3,"",데이터백업!C3&"->"&데이터!C3) | E3: =IF(데이터백업!D3=데이터!D3,"",데이터백업!D3&"->"&데이터!D3) | F3: =IF(데이터백업!E3=데이터!E3,"",데이터백업!E3&"->"&데이터!E3) | G3: =IF(데이터백업!F3=데이터!F3,"",데이터백업!F3&"->"&데이터!F3) | H3: =IF(데이터백업!G3=데이터!G3,"",데이터백업!G3&"->"&데이터!G3) | I3: =IF(데이터백업!H3=데이터!H3,"",데이터백업!H3&"->"&데이터!H3) | ... BK3: =IF(데이터백업!BJ3=데이터!BJ3,"",데이터백업!BJ3&"->"&데이터!BJ3)
A4: =IF(COUNTIF(B4:BK4,"*->*") > 0,"수정","") | B4: =IF(데이터백업!A4=데이터!A4,"",데이터백업!A4&"->"&데이터!A4) | C4: =IF(데이터백업!B4=데이터!B4,"",데이터백업!B4&"->"&데이터!B4) | D4: =IF(데이터백업!C4=데이터!C4,"",데이터백업!C4&"->"&데이터!C4) | E4: =IF(데이터백업!D4=데이터!D4,"",데이터백업!D4&"->"&데이터!D4) | F4: =IF(데이터백업!E4=데이터!E4,"",데이터백업!E4&"->"&데이터!E4) | G4: =IF(데이터백업!F4=데이터!F4,"",데이터백업!F4&"->"&데이터!F4) | H4: =IF(데이터백업!G4=데이터!G4,"",데이터백업!G4&"->"&데이터!G4) | I4: =IF(데이터백업!H4=데이터!H4,"",데이터백업!H4&"->"&데이터!H4) | ... BK4: =IF(데이터백업!BJ4=데이터!BJ4,"",데이터백업!BJ4&"->"&데이터!BJ4)
A5: =IF(COUNTIF(B5:BK5,"*->*") > 0,"수정","") | B5: =IF(데이터백업!A5=데이터!A5,"",데이터백업!A5&"->"&데이터!A5) | C5: =IF(데이터백업!B5=데이터!B5,"",데이터백업!B5&"->"&데이터!B5) | D5: =IF(데이터백업!C5=데이터!C5,"",데이터백업!C5&"->"&데이터!C5) | E5: =IF(데이터백업!D5=데이터!D5,"",데이터백업!D5&"->"&데이터!D5) | F5: =IF(데이터백업!E5=데이터!E5,"",데이터백업!E5&"->"&데이터!E5) | G5: =IF(데이터백업!F5=데이터!F5,"",데이터백업!F5&"->"&데이터!F5) | H5: =IF(데이터백업!G5=데이터!G5,"",데이터백업!G5&"->"&데이터!G5) | I5: =IF(데이터백업!H5=데이터!H5,"",데이터백업!H5&"->"&데이터!H5) | ... BK5: =IF(데이터백업!BJ5=데이터!BJ5,"",데이터백업!BJ5&"->"&데이터!BJ5)
A6: =IF(COUNTIF(B6:BK6,"*->*") > 0,"수정","") | B6: =IF(데이터백업!A6=데이터!A6,"",데이터백업!A6&"->"&데이터!A6) | C6: =IF(데이터백업!B6=데이터!B6,"",데이터백업!B6&"->"&데이터!B6) | D6: =IF(데이터백업!C6=데이터!C6,"",데이터백업!C6&"->"&데이터!C6) | E6: =IF(데이터백업!D6=데이터!D6,"",데이터백업!D6&"->"&데이터!D6) | F6: =IF(데이터백업!E6=데이터!E6,"",데이터백업!E6&"->"&데이터!E6) | G6: =IF(데이터백업!F6=데이터!F6,"",데이터백업!F6&"->"&데이터!F6) | H6: =IF(데이터백업!G6=데이터!G6,"",데이터백업!G6&"->"&데이터!G6) | I6: =IF(데이터백업!H6=데이터!H6,"",데이터백업!H6&"->"&데이터!H6) | ... BK6: =IF(데이터백업!BJ6=데이터!BJ6,"",데이터백업!BJ6&"->"&데이터!BJ6)
A7: =IF(COUNTIF(B7:BK7,"*->*") > 0,"수정","") | B7: =IF(데이터백업!A7=데이터!A7,"",데이터백업!A7&"->"&데이터!A7) | C7: =IF(데이터백업!B7=데이터!B7,"",데이터백업!B7&"->"&데이터!B7) | D7: =IF(데이터백업!C7=데이터!C7,"",데이터백업!C7&"->"&데이터!C7) | E7: =IF(데이터백업!D7=데이터!D7,"",데이터백업!D7&"->"&데이터!D7) | F7: =IF(데이터백업!E7=데이터!E7,"",데이터백업!E7&"->"&데이터!E7) | G7: =IF(데이터백업!F7=데이터!F7,"",데이터백업!F7&"->"&데이터!F7) | H7: =IF(데이터백업!G7=데이터!G7,"",데이터백업!G7&"->"&데이터!G7) | I7: =IF(데이터백업!H7=데이터!H7,"",데이터백업!H7&"->"&데이터!H7) | ... BK7: =IF(데이터백업!BJ7=데이터!BJ7,"",데이터백업!BJ7&"->"&데이터!BJ7)
A8: =IF(COUNTIF(B8:BK8,"*->*") > 0,"수정","") | B8: =IF(데이터백업!A8=데이터!A8,"",데이터백업!A8&"->"&데이터!A8) | C8: =IF(데이터백업!B8=데이터!B8,"",데이터백업!B8&"->"&데이터!B8) | D8: =IF(데이터백업!C8=데이터!C8,"",데이터백업!C8&"->"&데이터!C8) | E8: =IF(데이터백업!D8=데이터!D8,"",데이터백업!D8&"->"&데이터!D8) | F8: =IF(데이터백업!E8=데이터!E8,"",데이터백업!E8&"->"&데이터!E8) | G8: =IF(데이터백업!F8=데이터!F8,"",데이터백업!F8&"->"&데이터!F8) | H8: =IF(데이터백업!G8=데이터!G8,"",데이터백업!G8&"->"&데이터!G8) | I8: =IF(데이터백업!H8=데이터!H8,"",데이터백업!H8&"->"&데이터!H8) | ... BK8: =IF(데이터백업!BJ8=데이터!BJ8,"",데이터백업!BJ8&"->"&데이터!BJ8)
A9: =IF(COUNTIF(B9:BK9,"*->*") > 0,"수정","") | B9: =IF(데이터백업!A9=데이터!A9,"",데이터백업!A9&"->"&데이터!A9) | C9: =IF(데이터백업!B9=데이터!B9,"",데이터백업!B9&"->"&데이터!B9) | D9: =IF(데이터백업!C9=데이터!C9,"",데이터백업!C9&"->"&데이터!C9) | E9: =IF(데이터백업!D9=데이터!D9,"",데이터백업!D9&"->"&데이터!D9) | F9: =IF(데이터백업!E9=데이터!E9,"",데이터백업!E9&"->"&데이터!E9) | G9: =IF(데이터백업!F9=데이터!F9,"",데이터백업!F9&"->"&데이터!F9) | H9: =IF(데이터백업!G9=데이터!G9,"",데이터백업!G9&"->"&데이터!G9) | I9: =IF(데이터백업!H9=데이터!H9,"",데이터백업!H9&"->"&데이터!H9) | ... BK9: =IF(데이터백업!BJ9=데이터!BJ9,"",데이터백업!BJ9&"->"&데이터!BJ9)
A10: =IF(COUNTIF(B10:BK10,"*->*") > 0,"수정","") | B10: =IF(데이터백업!A10=데이터!A10,"",데이터백업!A10&"->"&데이터!A10) | C10: =IF(데이터백업!B10=데이터!B10,"",데이터백업!B10&"->"&데이터!B10) | D10: =IF(데이터백업!C10=데이터!C10,"",데이터백업!C10&"->"&데이터!C10) | E10: =IF(데이터백업!D10=데이터!D10,"",데이터백업!D10&"->"&데이터!D10) | F10: =IF(데이터백업!E10=데이터!E10,"",데이터백업!E10&"->"&데이터!E10) | G10: =IF(데이터백업!F10=데이터!F10,"",데이터백업!F10&"->"&데이터!F10) | H10: =IF(데이터백업!G10=데이터!G10,"",데이터백업!G10&"->"&데이터!G10) | I10: =IF(데이터백업!H10=데이터!H10,"",데이터백업!H10&"->"&데이터!H10) | ... BK10: =IF(데이터백업!BJ10=데이터!BJ10,"",데이터백업!BJ10&"->"&데이터!BJ10)
A11: =IF(COUNTIF(B11:BK11,"*->*") > 0,"수정","") | B11: =IF(데이터백업!A11=데이터!A11,"",데이터백업!A11&"->"&데이터!A11) | C11: =IF(데이터백업!B11=데이터!B11,"",데이터백업!B11&"->"&데이터!B11) | D11: =IF(데이터백업!C11=데이터!C11,"",데이터백업!C11&"->"&데이터!C11) | E11: =IF(데이터백업!D11=데이터!D11,"",데이터백업!D11&"->"&데이터!D11) | F11: =IF(데이터백업!E11=데이터!E11,"",데이터백업!E11&"->"&데이터!E11) | G11: =IF(데이터백업!F11=데이터!F11,"",데이터백업!F11&"->"&데이터!F11) | H11: =IF(데이터백업!G11=데이터!G11,"",데이터백업!G11&"->"&데이터!G11) | I11: =IF(데이터백업!H11=데이터!H11,"",데이터백업!H11&"->"&데이터!H11) | ... BK11: =IF(데이터백업!BJ11=데이터!BJ11,"",데이터백업!BJ11&"->"&데이터!BJ11)
A12: =IF(COUNTIF(B12:BK12,"*->*") > 0,"수정","") | B12: =IF(데이터백업!A12=데이터!A12,"",데이터백업!A12&"->"&데이터!A12) | C12: =IF(데이터백업!B12=데이터!B12,"",데이터백업!B12&"->"&데이터!B12) | D12: =IF(데이터백업!C12=데이터!C12,"",데이터백업!C12&"->"&데이터!C12) | E12: =IF(데이터백업!D12=데이터!D12,"",데이터백업!D12&"->"&데이터!D12) | F12: =IF(데이터백업!E12=데이터!E12,"",데이터백업!E12&"->"&데이터!E12) | G12: =IF(데이터백업!F12=데이터!F12,"",데이터백업!F12&"->"&데이터!F12) | H12: =IF(데이터백업!G12=데이터!G12,"",데이터백업!G12&"->"&데이터!G12) | I12: =IF(데이터백업!H12=데이터!H12,"",데이터백업!H12&"->"&데이터!H12) | ... BK12: =IF(데이터백업!BJ12=데이터!BJ12,"",데이터백업!BJ12&"->"&데이터!BJ12)
